{
  "name": "hut",
  "size": [
    7,
    8,
    7
  ],
  "palette": [
    {
      "id": 0,
      "block": "cobblestone"
    },
    {
      "id": 1,
      "block": "boards"
    },
    {
      "id": 2,
      "block": "wood"
    },
    {
      "id": 3,
      "block": "bookshelf"
    },
    {
      "id": 4,
      "block": "crafting_table"
    },
    {
      "id": 5,
      "block": "glass"
    },
    {
      "id": 6,
      "block": "torch"
    },
    {
      "id": 7,
      "block": "wood_stairs_south"
    },
    {
      "id": 8,
      "block": "wood_stairs_north"
    }
  ],
  "blocks": [
    {
      "pos": [
        1,
        0,
        1
      ],
      "state": 0
    },
    {
      "pos": [
        2,
        0,
        1
      ],
      "state": 0
    },
    {
      "pos": [
        3,
        0,
        1
      ],
      "state": 0
    },
    {
      "pos": [
        4,
        0,
        1
      ],
      "state": 0
    },
    {
      "pos": [
        5,
        0,
        1
      ],
      "state": 0
    },
    {
      "pos": [
        1,
        0,
        2
      ],
      "state": 0
    },
    {
      "pos": [
        2,
        0,
        2
      ],
      "state": 0
    },
    {
      "pos": [
        3,
        0,
        2
      ],
      "state": 0
    },
    {
      "pos": [
        4,
        0,
        2
      ],
      "state": 0
    },
    {
      "pos": [
        5,
        0,
        2
      ],
      "state": 0
    },
    {
      "pos": [
        1,
        0,
        3
      ],
      "state": 0
    },
    {
      "pos": [
        2,
        0,
        3
      ],
      "state": 0
    },
    {
      "pos": [
        3,
        0,
        3
      ],
      "state": 0
    },
    {
      "pos": [
        4,
        0,
        3
      ],
      "state": 0
    },
    {
      "pos": [
        5,
        0,
        3
      ],
      "state": 0
    },
    {
      "pos": [
        1,
        0,
        4
      ],
      "state": 0
    },
    {
      "pos": [
        2,
        0,
        4
      ],
      "state": 0
    },
    {
      "pos": [
        3,
        0,
        4
      ],
      "state": 0
    },
    {
      "pos": [
        4,
        0,
        4
      ],
      "state": 0
    },
    {
      "pos": [
        5,
        0,
        4
      ],
      "state": 0
    },
    {
      "pos": [
        1,
        0,
        5
      ],
      "state": 0
    },
    {
      "pos": [
        2,
        0,
        5
      ],
      "state": 0
    },
    {
      "pos": [
        3,
        0,
        5
      ],
      "state": 0
    },
    {
      "pos": [
        4,
        0,
        5
      ],
      "state": 0
    },
    {
      "pos": [
        5,
        0,
        5
      ],
      "state": 0
    },
    {
      "pos": [
        1,
        1,
        1
      ],
      "state": 1
    },
    {
      "pos": [
        2,
        1,
        1
      ],
      "state": 1
    },
    {
      "pos": [
        3,
        1,
        1
      ],
      "state": 1
    },
    {
      "pos": [
        4,
        1,
        1
      ],
      "state": 1
    },
    {
      "pos": [
        5,
        1,
        1
      ],
      "state": 1
    },
    {
      "pos": [
        1,
        1,
        2
      ],
      "state": 1
    },
    {
      "pos": [
        2,
        1,
        2
      ],
      "state": 1
    },
    {
      "pos": [
        3,
        1,
        2
      ],
      "state": 1
    },
    {
      "pos": [
        4,
        1,
        2
      ],
      "state": 1
    },
    {
      "pos": [
        5,
        1,
        2
      ],
      "state": 1
    },
    {
      "pos": [
        1,
        1,
        3
      ],
      "state": 1
    },
    {
      "pos": [
        2,
        1,
        3
      ],
      "state": 1
    },
    {
      "pos": [
        3,
        1,
        3
      ],
      "state": 1
    },
    {
      "pos": [
        4,
        1,
        3
      ],
      "state": 1
    },
    {
      "pos": [
        5,
        1,
        3
      ],
      "state": 1
    },
    {
      "pos": [
        1,
        1,
        4
      ],
      "state": 1
    },
    {
      "pos": [
        2,
        1,
        4
      ],
      "state": 1
    },
    {
      "pos": [
        3,
        1,
        4
      ],
      "state": 1
    },
    {
      "pos": [
        4,
        1,
        4
      ],
      "state": 1
    },
    {
      "pos": [
        5,
        1,
        4
      ],
      "state": 1
    },
    {
      "pos": [
        1,
        1,
        5
      ],
      "state": 1
    },
    {
      "pos": [
        2,
        1,
        5
      ],
      "state": 1
    },
    {
      "pos": [
        3,
        1,
        5
      ],
      "state": 1
    },
    {
      "pos": [
        4,
        1,
        5
      ],
      "state": 1
    },
    {
      "pos": [
        5,
        1,
        5
      ],
      "state": 1
    },
    {
      "pos": [
        1,
        2,
        1
      ],
      "state": 2
    },
    {
      "pos": [
        2,
        2,
        1
      ],
      "state": 1
    },
    {
      "pos": [
        3,
        2,
        1
      ],
      "state": 1
    },
    {
      "pos": [
        4,
        2,
        1
      ],
      "state": 1
    },
    {
      "pos": [
        5,
        2,
        1
      ],
      "state": 2
    },
    {
      "pos": [
        1,
        2,
        2
      ],
      "state": 1
    },
    {
      "pos": [
        5,
        2,
        2
      ],
      "state": 1
    },
    {
      "pos": [
        1,
        2,
        3
      ],
      "state": 1
    },
    {
      "pos": [
        5,
        2,
        3
      ],
      "state": 1
    },
    {
      "pos": [
        1,
        2,
        4
      ],
      "state": 1
    },
    {
      "pos": [
        2,
        2,
        4
      ],
      "state": 3
    },
    {
      "pos": [
        4,
        2,
        4
      ],
      "state": 4
    },
    {
      "pos": [
        5,
        2,
        4
      ],
      "state": 1
    },
    {
      "pos": [
        1,
        2,
        5
      ],
      "state": 2
    },
    {
      "pos": [
        2,
        2,
        5
      ],
      "state": 1
    },
    {
      "pos": [
        4,
        2,
        5
      ],
      "state": 1
    },
    {
      "pos": [
        5,
        2,
        5
      ],
      "state": 2
    },
    {
      "pos": [
        1,
        3,
        1
      ],
      "state": 2
    },
    {
      "pos": [
        2,
        3,
        1
      ],
      "state": 5
    },
    {
      "pos": [
        3,
        3,
        1
      ],
      "state": 1
    },
    {
      "pos": [
        4,
        3,
        1
      ],
      "state": 5
    },
    {
      "pos": [
        5,
        3,
        1
      ],
      "state": 2
    },
    {
      "pos": [
        1,
        3,
        2
      ],
      "state": 1
    },
    {
      "pos": [
        2,
        3,
        2
      ],
      "state": 6
    },
    {
      "pos": [
        4,
        3,
        2
      ],
      "state": 6
    },
    {
      "pos": [
        5,
        3,
        2
      ],
      "state": 1
    },
    {
      "pos": [
        1,
        3,
        3
      ],
      "state": 5
    },
    {
      "pos": [
        5,
        3,
        3
      ],
      "state": 5
    },
    {
      "pos": [
        1,
        3,
        4
      ],
      "state": 1
    },
    {
      "pos": [
        5,
        3,
        4
      ],
      "state": 1
    },
    {
      "pos": [
        1,
        3,
        5
      ],
      "state": 2
    },
    {
      "pos": [
        2,
        3,
        5
      ],
      "state": 1
    },
    {
      "pos": [
        4,
        3,
        5
      ],
      "state": 1
    },
    {
      "pos": [
        5,
        3,
        5
      ],
      "state": 2
    },
    {
      "pos": [
        1,
        4,
        1
      ],
      "state": 2
    },
    {
      "pos": [
        2,
        4,
        1
      ],
      "state": 1
    },
    {
      "pos": [
        3,
        4,
        1
      ],
      "state": 1
    },
    {
      "pos": [
        4,
        4,
        1
      ],
      "state": 1
    },
    {
      "pos": [
        5,
        4,
        1
      ],
      "state": 2
    },
    {
      "pos": [
        1,
        4,
        2
      ],
      "state": 1
    },
    {
      "pos": [
        5,
        4,
        2
      ],
      "state": 1
    },
    {
      "pos": [
        1,
        4,
        3
      ],
      "state": 1
    },
    {
      "pos": [
        5,
        4,
        3
      ],
      "state": 1
    },
    {
      "pos": [
        1,
        4,
        4
      ],
      "state": 1
    },
    {
      "pos": [
        5,
        4,
        4
      ],
      "state": 1
    },
    {
      "pos": [
        1,
        4,
        5
      ],
      "state": 2
    },
    {
      "pos": [
        2,
        4,
        5
      ],
      "state": 1
    },
    {
      "pos": [
        3,
        4,
        5
      ],
      "state": 1
    },
    {
      "pos": [
        4,
        4,
        5
      ],
      "state": 1
    },
    {
      "pos": [
        5,
        4,
        5
      ],
      "state": 2
    },
    {
      "pos": [
        0,
        5,
        0
      ],
      "state": 7
    },
    {
      "pos": [
        1,
        5,
        0
      ],
      "state": 7
    },
    {
      "pos": [
        2,
        5,
        0
      ],
      "state": 7
    },
    {
      "pos": [
        3,
        5,
        0
      ],
      "state": 7
    },
    {
      "pos": [
        4,
        5,
        0
      ],
      "state": 7
    },
    {
      "pos": [
        5,
        5,
        0
      ],
      "state": 7
    },
    {
      "pos": [
        6,
        5,
        0
      ],
      "state": 7
    },
    {
      "pos": [
        1,
        5,
        1
      ],
      "state": 1
    },
    {
      "pos": [
        2,
        5,
        1
      ],
      "state": 1
    },
    {
      "pos": [
        3,
        5,
        1
      ],
      "state": 1
    },
    {
      "pos": [
        4,
        5,
        1
      ],
      "state": 1
    },
    {
      "pos": [
        5,
        5,
        1
      ],
      "state": 1
    },
    {
      "pos": [
        1,
        5,
        2
      ],
      "state": 1
    },
    {
      "pos": [
        2,
        5,
        2
      ],
      "state": 1
    },
    {
      "pos": [
        3,
        5,
        2
      ],
      "state": 1
    },
    {
      "pos": [
        4,
        5,
        2
      ],
      "state": 1
    },
    {
      "pos": [
        5,
        5,
        2
      ],
      "state": 1
    },
    {
      "pos": [
        1,
        5,
        3
      ],
      "state": 1
    },
    {
      "pos": [
        2,
        5,
        3
      ],
      "state": 1
    },
    {
      "pos": [
        3,
        5,
        3
      ],
      "state": 1
    },
    {
      "pos": [
        4,
        5,
        3
      ],
      "state": 1
    },
    {
      "pos": [
        5,
        5,
        3
      ],
      "state": 1
    },
    {
      "pos": [
        1,
        5,
        4
      ],
      "state": 1
    },
    {
      "pos": [
        2,
        5,
        4
      ],
      "state": 1
    },
    {
      "pos": [
        3,
        5,
        4
      ],
      "state": 1
    },
    {
      "pos": [
        4,
        5,
        4
      ],
      "state": 1
    },
    {
      "pos": [
        5,
        5,
        4
      ],
      "state": 1
    },
    {
      "pos": [
        1,
        5,
        5
      ],
      "state": 1
    },
    {
      "pos": [
        2,
        5,
        5
      ],
      "state": 1
    },
    {
      "pos": [
        3,
        5,
        5
      ],
      "state": 1
    },
    {
      "pos": [
        4,
        5,
        5
      ],
      "state": 1
    },
    {
      "pos": [
        5,
        5,
        5
      ],
      "state": 1
    },
    {
      "pos": [
        0,
        5,
        6
      ],
      "state": 8
    },
    {
      "pos": [
        1,
        5,
        6
      ],
      "state": 8
    },
    {
      "pos": [
        2,
        5,
        6
      ],
      "state": 8
    },
    {
      "pos": [
        3,
        5,
        6
      ],
      "state": 8
    },
    {
      "pos": [
        4,
        5,
        6
      ],
      "state": 8
    },
    {
      "pos": [
        5,
        5,
        6
      ],
      "state": 8
    },
    {
      "pos": [
        6,
        5,
        6
      ],
      "state": 8
    },
    {
      "pos": [
        1,
        6,
        1
      ],
      "state": 7
    },
    {
      "pos": [
        2,
        6,
        1
      ],
      "state": 7
    },
    {
      "pos": [
        3,
        6,
        1
      ],
      "state": 7
    },
    {
      "pos": [
        4,
        6,
        1
      ],
      "state": 7
    },
    {
      "pos": [
        5,
        6,
        1
      ],
      "state": 7
    },
    {
      "pos": [
        1,
        6,
        5
      ],
      "state": 8
    },
    {
      "pos": [
        2,
        6,
        5
      ],
      "state": 8
    },
    {
      "pos": [
        3,
        6,
        5
      ],
      "state": 8
    },
    {
      "pos": [
        4,
        6,
        5
      ],
      "state": 8
    },
    {
      "pos": [
        5,
        6,
        5
      ],
      "state": 8
    },
    {
      "pos": [
        2,
        7,
        2
      ],
      "state": 7
    },
    {
      "pos": [
        3,
        7,
        2
      ],
      "state": 7
    },
    {
      "pos": [
        4,
        7,
        2
      ],
      "state": 7
    },
    {
      "pos": [
        2,
        7,
        3
      ],
      "state": 1
    },
    {
      "pos": [
        3,
        7,
        3
      ],
      "state": 1
    },
    {
      "pos": [
        4,
        7,
        3
      ],
      "state": 1
    },
    {
      "pos": [
        2,
        7,
        4
      ],
      "state": 8
    },
    {
      "pos": [
        3,
        7,
        4
      ],
      "state": 8
    },
    {
      "pos": [
        4,
        7,
        4
      ],
      "state": 8
    }
  ],
  "anchor": [
    3,
    0,
    3
  ],
  "groundOffset": -1,
  "rarity": 0.015625
}
