{
  "name": "mansion",
  "size": [
    20,
    12,
    20
  ],
  "palette": [
    {
      "id": 0,
      "block": "stone_bricks"
    },
    {
      "id": 1,
      "block": "dark_planks"
    },
    {
      "id": 2,
      "block": "wood_stairs_north"
    },
    {
      "id": 3,
      "block": "brick"
    },
    {
      "id": 4,
      "block": "boards"
    },
    {
      "id": 5,
      "block": "bookshelf"
    },
    {
      "id": 6,
      "block": "crafting_table"
    },
    {
      "id": 7,
      "block": "glass"
    },
    {
      "id": 8,
      "block": "torch"
    }
  ],
  "blocks": [
    {
      "pos": [
        0,
        0,
        0
      ],
      "state": 0
    },
    {
      "pos": [
        1,
        0,
        0
      ],
      "state": 0
    },
    {
      "pos": [
        2,
        0,
        0
      ],
      "state": 0
    },
    {
      "pos": [
        3,
        0,
        0
      ],
      "state": 0
    },
    {
      "pos": [
        4,
        0,
        0
      ],
      "state": 0
    },
    {
      "pos": [
        5,
        0,
        0
      ],
      "state": 0
    },
    {
      "pos": [
        6,
        0,
        0
      ],
      "state": 0
    },
    {
      "pos": [
        7,
        0,
        0
      ],
      "state": 0
    },
    {
      "pos": [
        8,
        0,
        0
      ],
      "state": 0
    },
    {
      "pos": [
        9,
        0,
        0
      ],
      "state": 0
    },
    {
      "pos": [
        10,
        0,
        0
      ],
      "state": 0
    },
    {
      "pos": [
        11,
        0,
        0
      ],
      "state": 0
    },
    {
      "pos": [
        12,
        0,
        0
      ],
      "state": 0
    },
    {
      "pos": [
        13,
        0,
        0
      ],
      "state": 0
    },
    {
      "pos": [
        14,
        0,
        0
      ],
      "state": 0
    },
    {
      "pos": [
        15,
        0,
        0
      ],
      "state": 0
    },
    {
      "pos": [
        16,
        0,
        0
      ],
      "state": 0
    },
    {
      "pos": [
        17,
        0,
        0
      ],
      "state": 0
    },
    {
      "pos": [
        18,
        0,
        0
      ],
      "state": 0
    },
    {
      "pos": [
        19,
        0,
        0
      ],
      "state": 0
    },
    {
      "pos": [
        0,
        0,
        1
      ],
      "state": 0
    },
    {
      "pos": [
        1,
        0,
        1
      ],
      "state": 0
    },
    {
      "pos": [
        2,
        0,
        1
      ],
      "state": 0
    },
    {
      "pos": [
        3,
        0,
        1
      ],
      "state": 0
    },
    {
      "pos": [
        4,
        0,
        1
      ],
      "state": 0
    },
    {
      "pos": [
        5,
        0,
        1
      ],
      "state": 0
    },
    {
      "pos": [
        6,
        0,
        1
      ],
      "state": 0
    },
    {
      "pos": [
        7,
        0,
        1
      ],
      "state": 0
    },
    {
      "pos": [
        8,
        0,
        1
      ],
      "state": 0
    },
    {
      "pos": [
        9,
        0,
        1
      ],
      "state": 0
    },
    {
      "pos": [
        10,
        0,
        1
      ],
      "state": 0
    },
    {
      "pos": [
        11,
        0,
        1
      ],
      "state": 0
    },
    {
      "pos": [
        12,
        0,
        1
      ],
      "state": 0
    },
    {
      "pos": [
        13,
        0,
        1
      ],
      "state": 0
    },
    {
      "pos": [
        14,
        0,
        1
      ],
      "state": 0
    },
    {
      "pos": [
        15,
        0,
        1
      ],
      "state": 0
    },
    {
      "pos": [
        16,
        0,
        1
      ],
      "state": 0
    },
    {
      "pos": [
        17,
        0,
        1
      ],
      "state": 0
    },
    {
      "pos": [
        18,
        0,
        1
      ],
      "state": 0
    },
    {
      "pos": [
        19,
        0,
        1
      ],
      "state": 0
    },
    {
      "pos": [
        0,
        0,
        2
      ],
      "state": 0
    },
    {
      "pos": [
        1,
        0,
        2
      ],
      "state": 0
    },
    {
      "pos": [
        2,
        0,
        2
      ],
      "state": 0
    },
    {
      "pos": [
        3,
        0,
        2
      ],
      "state": 0
    },
    {
      "pos": [
        4,
        0,
        2
      ],
      "state": 0
    },
    {
      "pos": [
        5,
        0,
        2
      ],
      "state": 0
    },
    {
      "pos": [
        6,
        0,
        2
      ],
      "state": 0
    },
    {
      "pos": [
        7,
        0,
        2
      ],
      "state": 0
    },
    {
      "pos": [
        8,
        0,
        2
      ],
      "state": 0
    },
    {
      "pos": [
        9,
        0,
        2
      ],
      "state": 0
    },
    {
      "pos": [
        10,
        0,
        2
      ],
      "state": 0
    },
    {
      "pos": [
        11,
        0,
        2
      ],
      "state": 0
    },
    {
      "pos": [
        12,
        0,
        2
      ],
      "state": 0
    },
    {
      "pos": [
        13,
        0,
        2
      ],
      "state": 0
    },
    {
      "pos": [
        14,
        0,
        2
      ],
      "state": 0
    },
    {
      "pos": [
        15,
        0,
        2
      ],
      "state": 0
    },
    {
      "pos": [
        16,
        0,
        2
      ],
      "state": 0
    },
    {
      "pos": [
        17,
        0,
        2
      ],
      "state": 0
    },
    {
      "pos": [
        18,
        0,
        2
      ],
      "state": 0
    },
    {
      "pos": [
        19,
        0,
        2
      ],
      "state": 0
    },
    {
      "pos": [
        0,
        0,
        3
      ],
      "state": 0
    },
    {
      "pos": [
        1,
        0,
        3
      ],
      "state": 0
    },
    {
      "pos": [
        2,
        0,
        3
      ],
      "state": 0
    },
    {
      "pos": [
        3,
        0,
        3
      ],
      "state": 0
    },
    {
      "pos": [
        4,
        0,
        3
      ],
      "state": 0
    },
    {
      "pos": [
        5,
        0,
        3
      ],
      "state": 0
    },
    {
      "pos": [
        6,
        0,
        3
      ],
      "state": 0
    },
    {
      "pos": [
        7,
        0,
        3
      ],
      "state": 0
    },
    {
      "pos": [
        8,
        0,
        3
      ],
      "state": 0
    },
    {
      "pos": [
        9,
        0,
        3
      ],
      "state": 0
    },
    {
      "pos": [
        10,
        0,
        3
      ],
      "state": 0
    },
    {
      "pos": [
        11,
        0,
        3
      ],
      "state": 0
    },
    {
      "pos": [
        12,
        0,
        3
      ],
      "state": 0
    },
    {
      "pos": [
        13,
        0,
        3
      ],
      "state": 0
    },
    {
      "pos": [
        14,
        0,
        3
      ],
      "state": 0
    },
    {
      "pos": [
        15,
        0,
        3
      ],
      "state": 0
    },
    {
      "pos": [
        16,
        0,
        3
      ],
      "state": 0
    },
    {
      "pos": [
        17,
        0,
        3
      ],
      "state": 0
    },
    {
      "pos": [
        18,
        0,
        3
      ],
      "state": 0
    },
    {
      "pos": [
        19,
        0,
        3
      ],
      "state": 0
    },
    {
      "pos": [
        0,
        0,
        4
      ],
      "state": 0
    },
    {
      "pos": [
        1,
        0,
        4
      ],
      "state": 0
    },
    {
      "pos": [
        2,
        0,
        4
      ],
      "state": 0
    },
    {
      "pos": [
        3,
        0,
        4
      ],
      "state": 0
    },
    {
      "pos": [
        4,
        0,
        4
      ],
      "state": 0
    },
    {
      "pos": [
        5,
        0,
        4
      ],
      "state": 0
    },
    {
      "pos": [
        6,
        0,
        4
      ],
      "state": 0
    },
    {
      "pos": [
        7,
        0,
        4
      ],
      "state": 0
    },
    {
      "pos": [
        8,
        0,
        4
      ],
      "state": 0
    },
    {
      "pos": [
        9,
        0,
        4
      ],
      "state": 0
    },
    {
      "pos": [
        10,
        0,
        4
      ],
      "state": 0
    },
    {
      "pos": [
        11,
        0,
        4
      ],
      "state": 0
    },
    {
      "pos": [
        12,
        0,
        4
      ],
      "state": 0
    },
    {
      "pos": [
        13,
        0,
        4
      ],
      "state": 0
    },
    {
      "pos": [
        14,
        0,
        4
      ],
      "state": 0
    },
    {
      "pos": [
        15,
        0,
        4
      ],
      "state": 0
    },
    {
      "pos": [
        16,
        0,
        4
      ],
      "state": 0
    },
    {
      "pos": [
        17,
        0,
        4
      ],
      "state": 0
    },
    {
      "pos": [
        18,
        0,
        4
      ],
      "state": 0
    },
    {
      "pos": [
        19,
        0,
        4
      ],
      "state": 0
    },
    {
      "pos": [
        0,
        0,
        5
      ],
      "state": 0
    },
    {
      "pos": [
        1,
        0,
        5
      ],
      "state": 0
    },
    {
      "pos": [
        2,
        0,
        5
      ],
      "state": 0
    },
    {
      "pos": [
        3,
        0,
        5
      ],
      "state": 0
    },
    {
      "pos": [
        4,
        0,
        5
      ],
      "state": 0
    },
    {
      "pos": [
        5,
        0,
        5
      ],
      "state": 0
    },
    {
      "pos": [
        6,
        0,
        5
      ],
      "state": 0
    },
    {
      "pos": [
        7,
        0,
        5
      ],
      "state": 0
    },
    {
      "pos": [
        8,
        0,
        5
      ],
      "state": 0
    },
    {
      "pos": [
        9,
        0,
        5
      ],
      "state": 0
    },
    {
      "pos": [
        10,
        0,
        5
      ],
      "state": 0
    },
    {
      "pos": [
        11,
        0,
        5
      ],
      "state": 0
    },
    {
      "pos": [
        12,
        0,
        5
      ],
      "state": 0
    },
    {
      "pos": [
        13,
        0,
        5
      ],
      "state": 0
    },
    {
      "pos": [
        14,
        0,
        5
      ],
      "state": 0
    },
    {
      "pos": [
        15,
        0,
        5
      ],
      "state": 0
    },
    {
      "pos": [
        16,
        0,
        5
      ],
      "state": 0
    },
    {
      "pos": [
        17,
        0,
        5
      ],
      "state": 0
    },
    {
      "pos": [
        18,
        0,
        5
      ],
      "state": 0
    },
    {
      "pos": [
        19,
        0,
        5
      ],
      "state": 0
    },
    {
      "pos": [
        0,
        0,
        6
      ],
      "state": 0
    },
    {
      "pos": [
        1,
        0,
        6
      ],
      "state": 0
    },
    {
      "pos": [
        2,
        0,
        6
      ],
      "state": 0
    },
    {
      "pos": [
        3,
        0,
        6
      ],
      "state": 0
    },
    {
      "pos": [
        4,
        0,
        6
      ],
      "state": 0
    },
    {
      "pos": [
        5,
        0,
        6
      ],
      "state": 0
    },
    {
      "pos": [
        6,
        0,
        6
      ],
      "state": 0
    },
    {
      "pos": [
        7,
        0,
        6
      ],
      "state": 0
    },
    {
      "pos": [
        8,
        0,
        6
      ],
      "state": 0
    },
    {
      "pos": [
        9,
        0,
        6
      ],
      "state": 0
    },
    {
      "pos": [
        10,
        0,
        6
      ],
      "state": 0
    },
    {
      "pos": [
        11,
        0,
        6
      ],
      "state": 0
    },
    {
      "pos": [
        12,
        0,
        6
      ],
      "state": 0
    },
    {
      "pos": [
        13,
        0,
        6
      ],
      "state": 0
    },
    {
      "pos": [
        14,
        0,
        6
      ],
      "state": 0
    },
    {
      "pos": [
        15,
        0,
        6
      ],
      "state": 0
    },
    {
      "pos": [
        16,
        0,
        6
      ],
      "state": 0
    },
    {
      "pos": [
        17,
        0,
        6
      ],
      "state": 0
    },
    {
      "pos": [
        18,
        0,
        6
      ],
      "state": 0
    },
    {
      "pos": [
        19,
        0,
        6
      ],
      "state": 0
    },
    {
      "pos": [
        0,
        0,
        7
      ],
      "state": 0
    },
    {
      "pos": [
        1,
        0,
        7
      ],
      "state": 0
    },
    {
      "pos": [
        2,
        0,
        7
      ],
      "state": 0
    },
    {
      "pos": [
        3,
        0,
        7
      ],
      "state": 0
    },
    {
      "pos": [
        4,
        0,
        7
      ],
      "state": 0
    },
    {
      "pos": [
        5,
        0,
        7
      ],
      "state": 0
    },
    {
      "pos": [
        6,
        0,
        7
      ],
      "state": 0
    },
    {
      "pos": [
        7,
        0,
        7
      ],
      "state": 0
    },
    {
      "pos": [
        8,
        0,
        7
      ],
      "state": 0
    },
    {
      "pos": [
        9,
        0,
        7
      ],
      "state": 0
    },
    {
      "pos": [
        10,
        0,
        7
      ],
      "state": 0
    },
    {
      "pos": [
        11,
        0,
        7
      ],
      "state": 0
    },
    {
      "pos": [
        12,
        0,
        7
      ],
      "state": 0
    },
    {
      "pos": [
        13,
        0,
        7
      ],
      "state": 0
    },
    {
      "pos": [
        14,
        0,
        7
      ],
      "state": 0
    },
    {
      "pos": [
        15,
        0,
        7
      ],
      "state": 0
    },
    {
      "pos": [
        16,
        0,
        7
      ],
      "state": 0
    },
    {
      "pos": [
        17,
        0,
        7
      ],
      "state": 0
    },
    {
      "pos": [
        18,
        0,
        7
      ],
      "state": 0
    },
    {
      "pos": [
        19,
        0,
        7
      ],
      "state": 0
    },
    {
      "pos": [
        0,
        0,
        8
      ],
      "state": 0
    },
    {
      "pos": [
        1,
        0,
        8
      ],
      "state": 0
    },
    {
      "pos": [
        2,
        0,
        8
      ],
      "state": 0
    },
    {
      "pos": [
        3,
        0,
        8
      ],
      "state": 0
    },
    {
      "pos": [
        4,
        0,
        8
      ],
      "state": 0
    },
    {
      "pos": [
        5,
        0,
        8
      ],
      "state": 0
    },
    {
      "pos": [
        6,
        0,
        8
      ],
      "state": 0
    },
    {
      "pos": [
        7,
        0,
        8
      ],
      "state": 0
    },
    {
      "pos": [
        8,
        0,
        8
      ],
      "state": 0
    },
    {
      "pos": [
        9,
        0,
        8
      ],
      "state": 0
    },
    {
      "pos": [
        10,
        0,
        8
      ],
      "state": 0
    },
    {
      "pos": [
        11,
        0,
        8
      ],
      "state": 0
    },
    {
      "pos": [
        12,
        0,
        8
      ],
      "state": 0
    },
    {
      "pos": [
        13,
        0,
        8
      ],
      "state": 0
    },
    {
      "pos": [
        14,
        0,
        8
      ],
      "state": 0
    },
    {
      "pos": [
        15,
        0,
        8
      ],
      "state": 0
    },
    {
      "pos": [
        16,
        0,
        8
      ],
      "state": 0
    },
    {
      "pos": [
        17,
        0,
        8
      ],
      "state": 0
    },
    {
      "pos": [
        18,
        0,
        8
      ],
      "state": 0
    },
    {
      "pos": [
        19,
        0,
        8
      ],
      "state": 0
    },
    {
      "pos": [
        0,
        0,
        9
      ],
      "state": 0
    },
    {
      "pos": [
        1,
        0,
        9
      ],
      "state": 0
    },
    {
      "pos": [
        2,
        0,
        9
      ],
      "state": 0
    },
    {
      "pos": [
        3,
        0,
        9
      ],
      "state": 0
    },
    {
      "pos": [
        4,
        0,
        9
      ],
      "state": 0
    },
    {
      "pos": [
        5,
        0,
        9
      ],
      "state": 0
    },
    {
      "pos": [
        6,
        0,
        9
      ],
      "state": 0
    },
    {
      "pos": [
        7,
        0,
        9
      ],
      "state": 0
    },
    {
      "pos": [
        8,
        0,
        9
      ],
      "state": 0
    },
    {
      "pos": [
        9,
        0,
        9
      ],
      "state": 0
    },
    {
      "pos": [
        10,
        0,
        9
      ],
      "state": 0
    },
    {
      "pos": [
        11,
        0,
        9
      ],
      "state": 0
    },
    {
      "pos": [
        12,
        0,
        9
      ],
      "state": 0
    },
    {
      "pos": [
        13,
        0,
        9
      ],
      "state": 0
    },
    {
      "pos": [
        14,
        0,
        9
      ],
      "state": 0
    },
    {
      "pos": [
        15,
        0,
        9
      ],
      "state": 0
    },
    {
      "pos": [
        16,
        0,
        9
      ],
      "state": 0
    },
    {
      "pos": [
        17,
        0,
        9
      ],
      "state": 0
    },
    {
      "pos": [
        18,
        0,
        9
      ],
      "state": 0
    },
    {
      "pos": [
        19,
        0,
        9
      ],
      "state": 0
    },
    {
      "pos": [
        0,
        0,
        10
      ],
      "state": 0
    },
    {
      "pos": [
        1,
        0,
        10
      ],
      "state": 0
    },
    {
      "pos": [
        2,
        0,
        10
      ],
      "state": 0
    },
    {
      "pos": [
        3,
        0,
        10
      ],
      "state": 0
    },
    {
      "pos": [
        4,
        0,
        10
      ],
      "state": 0
    },
    {
      "pos": [
        5,
        0,
        10
      ],
      "state": 0
    },
    {
      "pos": [
        6,
        0,
        10
      ],
      "state": 0
    },
    {
      "pos": [
        7,
        0,
        10
      ],
      "state": 0
    },
    {
      "pos": [
        8,
        0,
        10
      ],
      "state": 0
    },
    {
      "pos": [
        9,
        0,
        10
      ],
      "state": 0
    },
    {
      "pos": [
        10,
        0,
        10
      ],
      "state": 0
    },
    {
      "pos": [
        11,
        0,
        10
      ],
      "state": 0
    },
    {
      "pos": [
        12,
        0,
        10
      ],
      "state": 0
    },
    {
      "pos": [
        13,
        0,
        10
      ],
      "state": 0
    },
    {
      "pos": [
        14,
        0,
        10
      ],
      "state": 0
    },
    {
      "pos": [
        15,
        0,
        10
      ],
      "state": 0
    },
    {
      "pos": [
        16,
        0,
        10
      ],
      "state": 0
    },
    {
      "pos": [
        17,
        0,
        10
      ],
      "state": 0
    },
    {
      "pos": [
        18,
        0,
        10
      ],
      "state": 0
    },
    {
      "pos": [
        19,
        0,
        10
      ],
      "state": 0
    },
    {
      "pos": [
        0,
        0,
        11
      ],
      "state": 0
    },
    {
      "pos": [
        1,
        0,
        11
      ],
      "state": 0
    },
    {
      "pos": [
        2,
        0,
        11
      ],
      "state": 0
    },
    {
      "pos": [
        3,
        0,
        11
      ],
      "state": 0
    },
    {
      "pos": [
        4,
        0,
        11
      ],
      "state": 0
    },
    {
      "pos": [
        5,
        0,
        11
      ],
      "state": 0
    },
    {
      "pos": [
        6,
        0,
        11
      ],
      "state": 0
    },
    {
      "pos": [
        7,
        0,
        11
      ],
      "state": 0
    },
    {
      "pos": [
        8,
        0,
        11
      ],
      "state": 0
    },
    {
      "pos": [
        9,
        0,
        11
      ],
      "state": 0
    },
    {
      "pos": [
        10,
        0,
        11
      ],
      "state": 0
    },
    {
      "pos": [
        11,
        0,
        11
      ],
      "state": 0
    },
    {
      "pos": [
        12,
        0,
        11
      ],
      "state": 0
    },
    {
      "pos": [
        13,
        0,
        11
      ],
      "state": 0
    },
    {
      "pos": [
        14,
        0,
        11
      ],
      "state": 0
    },
    {
      "pos": [
        15,
        0,
        11
      ],
      "state": 0
    },
    {
      "pos": [
        16,
        0,
        11
      ],
      "state": 0
    },
    {
      "pos": [
        17,
        0,
        11
      ],
      "state": 0
    },
    {
      "pos": [
        18,
        0,
        11
      ],
      "state": 0
    },
    {
      "pos": [
        19,
        0,
        11
      ],
      "state": 0
    },
    {
      "pos": [
        0,
        0,
        12
      ],
      "state": 0
    },
    {
      "pos": [
        1,
        0,
        12
      ],
      "state": 0
    },
    {
      "pos": [
        2,
        0,
        12
      ],
      "state": 0
    },
    {
      "pos": [
        3,
        0,
        12
      ],
      "state": 0
    },
    {
      "pos": [
        4,
        0,
        12
      ],
      "state": 0
    },
    {
      "pos": [
        5,
        0,
        12
      ],
      "state": 0
    },
    {
      "pos": [
        6,
        0,
        12
      ],
      "state": 0
    },
    {
      "pos": [
        7,
        0,
        12
      ],
      "state": 0
    },
    {
      "pos": [
        8,
        0,
        12
      ],
      "state": 0
    },
    {
      "pos": [
        9,
        0,
        12
      ],
      "state": 0
    },
    {
      "pos": [
        10,
        0,
        12
      ],
      "state": 0
    },
    {
      "pos": [
        11,
        0,
        12
      ],
      "state": 0
    },
    {
      "pos": [
        12,
        0,
        12
      ],
      "state": 0
    },
    {
      "pos": [
        13,
        0,
        12
      ],
      "state": 0
    },
    {
      "pos": [
        14,
        0,
        12
      ],
      "state": 0
    },
    {
      "pos": [
        15,
        0,
        12
      ],
      "state": 0
    },
    {
      "pos": [
        16,
        0,
        12
      ],
      "state": 0
    },
    {
      "pos": [
        17,
        0,
        12
      ],
      "state": 0
    },
    {
      "pos": [
        18,
        0,
        12
      ],
      "state": 0
    },
    {
      "pos": [
        19,
        0,
        12
      ],
      "state": 0
    },
    {
      "pos": [
        0,
        0,
        13
      ],
      "state": 0
    },
    {
      "pos": [
        1,
        0,
        13
      ],
      "state": 0
    },
    {
      "pos": [
        2,
        0,
        13
      ],
      "state": 0
    },
    {
      "pos": [
        3,
        0,
        13
      ],
      "state": 0
    },
    {
      "pos": [
        4,
        0,
        13
      ],
      "state": 0
    },
    {
      "pos": [
        5,
        0,
        13
      ],
      "state": 0
    },
    {
      "pos": [
        6,
        0,
        13
      ],
      "state": 0
    },
    {
      "pos": [
        7,
        0,
        13
      ],
      "state": 0
    },
    {
      "pos": [
        8,
        0,
        13
      ],
      "state": 0
    },
    {
      "pos": [
        9,
        0,
        13
      ],
      "state": 0
    },
    {
      "pos": [
        10,
        0,
        13
      ],
      "state": 0
    },
    {
      "pos": [
        11,
        0,
        13
      ],
      "state": 0
    },
    {
      "pos": [
        12,
        0,
        13
      ],
      "state": 0
    },
    {
      "pos": [
        13,
        0,
        13
      ],
      "state": 0
    },
    {
      "pos": [
        14,
        0,
        13
      ],
      "state": 0
    },
    {
      "pos": [
        15,
        0,
        13
      ],
      "state": 0
    },
    {
      "pos": [
        16,
        0,
        13
      ],
      "state": 0
    },
    {
      "pos": [
        17,
        0,
        13
      ],
      "state": 0
    },
    {
      "pos": [
        18,
        0,
        13
      ],
      "state": 0
    },
    {
      "pos": [
        19,
        0,
        13
      ],
      "state": 0
    },
    {
      "pos": [
        0,
        0,
        14
      ],
      "state": 0
    },
    {
      "pos": [
        1,
        0,
        14
      ],
      "state": 0
    },
    {
      "pos": [
        2,
        0,
        14
      ],
      "state": 0
    },
    {
      "pos": [
        3,
        0,
        14
      ],
      "state": 0
    },
    {
      "pos": [
        4,
        0,
        14
      ],
      "state": 0
    },
    {
      "pos": [
        5,
        0,
        14
      ],
      "state": 0
    },
    {
      "pos": [
        6,
        0,
        14
      ],
      "state": 0
    },
    {
      "pos": [
        7,
        0,
        14
      ],
      "state": 0
    },
    {
      "pos": [
        8,
        0,
        14
      ],
      "state": 0
    },
    {
      "pos": [
        9,
        0,
        14
      ],
      "state": 0
    },
    {
      "pos": [
        10,
        0,
        14
      ],
      "state": 0
    },
    {
      "pos": [
        11,
        0,
        14
      ],
      "state": 0
    },
    {
      "pos": [
        12,
        0,
        14
      ],
      "state": 0
    },
    {
      "pos": [
        13,
        0,
        14
      ],
      "state": 0
    },
    {
      "pos": [
        14,
        0,
        14
      ],
      "state": 0
    },
    {
      "pos": [
        15,
        0,
        14
      ],
      "state": 0
    },
    {
      "pos": [
        16,
        0,
        14
      ],
      "state": 0
    },
    {
      "pos": [
        17,
        0,
        14
      ],
      "state": 0
    },
    {
      "pos": [
        18,
        0,
        14
      ],
      "state": 0
    },
    {
      "pos": [
        19,
        0,
        14
      ],
      "state": 0
    },
    {
      "pos": [
        0,
        0,
        15
      ],
      "state": 0
    },
    {
      "pos": [
        1,
        0,
        15
      ],
      "state": 0
    },
    {
      "pos": [
        2,
        0,
        15
      ],
      "state": 0
    },
    {
      "pos": [
        3,
        0,
        15
      ],
      "state": 0
    },
    {
      "pos": [
        4,
        0,
        15
      ],
      "state": 0
    },
    {
      "pos": [
        5,
        0,
        15
      ],
      "state": 0
    },
    {
      "pos": [
        6,
        0,
        15
      ],
      "state": 0
    },
    {
      "pos": [
        7,
        0,
        15
      ],
      "state": 0
    },
    {
      "pos": [
        8,
        0,
        15
      ],
      "state": 0
    },
    {
      "pos": [
        9,
        0,
        15
      ],
      "state": 0
    },
    {
      "pos": [
        10,
        0,
        15
      ],
      "state": 0
    },
    {
      "pos": [
        11,
        0,
        15
      ],
      "state": 0
    },
    {
      "pos": [
        12,
        0,
        15
      ],
      "state": 0
    },
    {
      "pos": [
        13,
        0,
        15
      ],
      "state": 0
    },
    {
      "pos": [
        14,
        0,
        15
      ],
      "state": 0
    },
    {
      "pos": [
        15,
        0,
        15
      ],
      "state": 0
    },
    {
      "pos": [
        16,
        0,
        15
      ],
      "state": 0
    },
    {
      "pos": [
        17,
        0,
        15
      ],
      "state": 0
    },
    {
      "pos": [
        18,
        0,
        15
      ],
      "state": 0
    },
    {
      "pos": [
        19,
        0,
        15
      ],
      "state": 0
    },
    {
      "pos": [
        0,
        0,
        16
      ],
      "state": 0
    },
    {
      "pos": [
        1,
        0,
        16
      ],
      "state": 0
    },
    {
      "pos": [
        2,
        0,
        16
      ],
      "state": 0
    },
    {
      "pos": [
        3,
        0,
        16
      ],
      "state": 0
    },
    {
      "pos": [
        4,
        0,
        16
      ],
      "state": 0
    },
    {
      "pos": [
        5,
        0,
        16
      ],
      "state": 0
    },
    {
      "pos": [
        6,
        0,
        16
      ],
      "state": 0
    },
    {
      "pos": [
        7,
        0,
        16
      ],
      "state": 0
    },
    {
      "pos": [
        8,
        0,
        16
      ],
      "state": 0
    },
    {
      "pos": [
        9,
        0,
        16
      ],
      "state": 0
    },
    {
      "pos": [
        10,
        0,
        16
      ],
      "state": 0
    },
    {
      "pos": [
        11,
        0,
        16
      ],
      "state": 0
    },
    {
      "pos": [
        12,
        0,
        16
      ],
      "state": 0
    },
    {
      "pos": [
        13,
        0,
        16
      ],
      "state": 0
    },
    {
      "pos": [
        14,
        0,
        16
      ],
      "state": 0
    },
    {
      "pos": [
        15,
        0,
        16
      ],
      "state": 0
    },
    {
      "pos": [
        16,
        0,
        16
      ],
      "state": 0
    },
    {
      "pos": [
        17,
        0,
        16
      ],
      "state": 0
    },
    {
      "pos": [
        18,
        0,
        16
      ],
      "state": 0
    },
    {
      "pos": [
        19,
        0,
        16
      ],
      "state": 0
    },
    {
      "pos": [
        0,
        0,
        17
      ],
      "state": 0
    },
    {
      "pos": [
        1,
        0,
        17
      ],
      "state": 0
    },
    {
      "pos": [
        2,
        0,
        17
      ],
      "state": 0
    },
    {
      "pos": [
        3,
        0,
        17
      ],
      "state": 0
    },
    {
      "pos": [
        4,
        0,
        17
      ],
      "state": 0
    },
    {
      "pos": [
        5,
        0,
        17
      ],
      "state": 0
    },
    {
      "pos": [
        6,
        0,
        17
      ],
      "state": 0
    },
    {
      "pos": [
        7,
        0,
        17
      ],
      "state": 0
    },
    {
      "pos": [
        8,
        0,
        17
      ],
      "state": 0
    },
    {
      "pos": [
        9,
        0,
        17
      ],
      "state": 0
    },
    {
      "pos": [
        10,
        0,
        17
      ],
      "state": 0
    },
    {
      "pos": [
        11,
        0,
        17
      ],
      "state": 0
    },
    {
      "pos": [
        12,
        0,
        17
      ],
      "state": 0
    },
    {
      "pos": [
        13,
        0,
        17
      ],
      "state": 0
    },
    {
      "pos": [
        14,
        0,
        17
      ],
      "state": 0
    },
    {
      "pos": [
        15,
        0,
        17
      ],
      "state": 0
    },
    {
      "pos": [
        16,
        0,
        17
      ],
      "state": 0
    },
    {
      "pos": [
        17,
        0,
        17
      ],
      "state": 0
    },
    {
      "pos": [
        18,
        0,
        17
      ],
      "state": 0
    },
    {
      "pos": [
        19,
        0,
        17
      ],
      "state": 0
    },
    {
      "pos": [
        0,
        0,
        18
      ],
      "state": 0
    },
    {
      "pos": [
        1,
        0,
        18
      ],
      "state": 0
    },
    {
      "pos": [
        2,
        0,
        18
      ],
      "state": 0
    },
    {
      "pos": [
        3,
        0,
        18
      ],
      "state": 0
    },
    {
      "pos": [
        4,
        0,
        18
      ],
      "state": 0
    },
    {
      "pos": [
        5,
        0,
        18
      ],
      "state": 0
    },
    {
      "pos": [
        6,
        0,
        18
      ],
      "state": 0
    },
    {
      "pos": [
        7,
        0,
        18
      ],
      "state": 0
    },
    {
      "pos": [
        8,
        0,
        18
      ],
      "state": 0
    },
    {
      "pos": [
        9,
        0,
        18
      ],
      "state": 0
    },
    {
      "pos": [
        10,
        0,
        18
      ],
      "state": 0
    },
    {
      "pos": [
        11,
        0,
        18
      ],
      "state": 0
    },
    {
      "pos": [
        12,
        0,
        18
      ],
      "state": 0
    },
    {
      "pos": [
        13,
        0,
        18
      ],
      "state": 0
    },
    {
      "pos": [
        14,
        0,
        18
      ],
      "state": 0
    },
    {
      "pos": [
        15,
        0,
        18
      ],
      "state": 0
    },
    {
      "pos": [
        16,
        0,
        18
      ],
      "state": 0
    },
    {
      "pos": [
        17,
        0,
        18
      ],
      "state": 0
    },
    {
      "pos": [
        18,
        0,
        18
      ],
      "state": 0
    },
    {
      "pos": [
        19,
        0,
        18
      ],
      "state": 0
    },
    {
      "pos": [
        0,
        0,
        19
      ],
      "state": 0
    },
    {
      "pos": [
        1,
        0,
        19
      ],
      "state": 0
    },
    {
      "pos": [
        2,
        0,
        19
      ],
      "state": 0
    },
    {
      "pos": [
        3,
        0,
        19
      ],
      "state": 0
    },
    {
      "pos": [
        4,
        0,
        19
      ],
      "state": 0
    },
    {
      "pos": [
        5,
        0,
        19
      ],
      "state": 0
    },
    {
      "pos": [
        6,
        0,
        19
      ],
      "state": 0
    },
    {
      "pos": [
        7,
        0,
        19
      ],
      "state": 0
    },
    {
      "pos": [
        8,
        0,
        19
      ],
      "state": 0
    },
    {
      "pos": [
        9,
        0,
        19
      ],
      "state": 0
    },
    {
      "pos": [
        10,
        0,
        19
      ],
      "state": 0
    },
    {
      "pos": [
        11,
        0,
        19
      ],
      "state": 0
    },
    {
      "pos": [
        12,
        0,
        19
      ],
      "state": 0
    },
    {
      "pos": [
        13,
        0,
        19
      ],
      "state": 0
    },
    {
      "pos": [
        14,
        0,
        19
      ],
      "state": 0
    },
    {
      "pos": [
        15,
        0,
        19
      ],
      "state": 0
    },
    {
      "pos": [
        16,
        0,
        19
      ],
      "state": 0
    },
    {
      "pos": [
        17,
        0,
        19
      ],
      "state": 0
    },
    {
      "pos": [
        18,
        0,
        19
      ],
      "state": 0
    },
    {
      "pos": [
        19,
        0,
        19
      ],
      "state": 0
    },
    {
      "pos": [
        1,
        1,
        1
      ],
      "state": 1
    },
    {
      "pos": [
        2,
        1,
        1
      ],
      "state": 1
    },
    {
      "pos": [
        3,
        1,
        1
      ],
      "state": 1
    },
    {
      "pos": [
        4,
        1,
        1
      ],
      "state": 1
    },
    {
      "pos": [
        5,
        1,
        1
      ],
      "state": 1
    },
    {
      "pos": [
        6,
        1,
        1
      ],
      "state": 1
    },
    {
      "pos": [
        7,
        1,
        1
      ],
      "state": 1
    },
    {
      "pos": [
        8,
        1,
        1
      ],
      "state": 1
    },
    {
      "pos": [
        9,
        1,
        1
      ],
      "state": 1
    },
    {
      "pos": [
        10,
        1,
        1
      ],
      "state": 1
    },
    {
      "pos": [
        11,
        1,
        1
      ],
      "state": 1
    },
    {
      "pos": [
        12,
        1,
        1
      ],
      "state": 1
    },
    {
      "pos": [
        13,
        1,
        1
      ],
      "state": 1
    },
    {
      "pos": [
        14,
        1,
        1
      ],
      "state": 1
    },
    {
      "pos": [
        15,
        1,
        1
      ],
      "state": 1
    },
    {
      "pos": [
        16,
        1,
        1
      ],
      "state": 1
    },
    {
      "pos": [
        17,
        1,
        1
      ],
      "state": 1
    },
    {
      "pos": [
        18,
        1,
        1
      ],
      "state": 1
    },
    {
      "pos": [
        1,
        1,
        2
      ],
      "state": 1
    },
    {
      "pos": [
        2,
        1,
        2
      ],
      "state": 1
    },
    {
      "pos": [
        3,
        1,
        2
      ],
      "state": 1
    },
    {
      "pos": [
        4,
        1,
        2
      ],
      "state": 1
    },
    {
      "pos": [
        5,
        1,
        2
      ],
      "state": 1
    },
    {
      "pos": [
        6,
        1,
        2
      ],
      "state": 1
    },
    {
      "pos": [
        7,
        1,
        2
      ],
      "state": 1
    },
    {
      "pos": [
        8,
        1,
        2
      ],
      "state": 1
    },
    {
      "pos": [
        9,
        1,
        2
      ],
      "state": 1
    },
    {
      "pos": [
        10,
        1,
        2
      ],
      "state": 1
    },
    {
      "pos": [
        11,
        1,
        2
      ],
      "state": 1
    },
    {
      "pos": [
        12,
        1,
        2
      ],
      "state": 1
    },
    {
      "pos": [
        13,
        1,
        2
      ],
      "state": 1
    },
    {
      "pos": [
        14,
        1,
        2
      ],
      "state": 1
    },
    {
      "pos": [
        15,
        1,
        2
      ],
      "state": 1
    },
    {
      "pos": [
        16,
        1,
        2
      ],
      "state": 1
    },
    {
      "pos": [
        17,
        1,
        2
      ],
      "state": 1
    },
    {
      "pos": [
        18,
        1,
        2
      ],
      "state": 1
    },
    {
      "pos": [
        1,
        1,
        3
      ],
      "state": 1
    },
    {
      "pos": [
        2,
        1,
        3
      ],
      "state": 1
    },
    {
      "pos": [
        3,
        1,
        3
      ],
      "state": 1
    },
    {
      "pos": [
        4,
        1,
        3
      ],
      "state": 1
    },
    {
      "pos": [
        5,
        1,
        3
      ],
      "state": 1
    },
    {
      "pos": [
        6,
        1,
        3
      ],
      "state": 1
    },
    {
      "pos": [
        7,
        1,
        3
      ],
      "state": 1
    },
    {
      "pos": [
        8,
        1,
        3
      ],
      "state": 1
    },
    {
      "pos": [
        9,
        1,
        3
      ],
      "state": 1
    },
    {
      "pos": [
        10,
        1,
        3
      ],
      "state": 1
    },
    {
      "pos": [
        11,
        1,
        3
      ],
      "state": 1
    },
    {
      "pos": [
        12,
        1,
        3
      ],
      "state": 1
    },
    {
      "pos": [
        13,
        1,
        3
      ],
      "state": 1
    },
    {
      "pos": [
        14,
        1,
        3
      ],
      "state": 1
    },
    {
      "pos": [
        15,
        1,
        3
      ],
      "state": 1
    },
    {
      "pos": [
        16,
        1,
        3
      ],
      "state": 1
    },
    {
      "pos": [
        17,
        1,
        3
      ],
      "state": 1
    },
    {
      "pos": [
        18,
        1,
        3
      ],
      "state": 1
    },
    {
      "pos": [
        1,
        1,
        4
      ],
      "state": 1
    },
    {
      "pos": [
        2,
        1,
        4
      ],
      "state": 1
    },
    {
      "pos": [
        3,
        1,
        4
      ],
      "state": 1
    },
    {
      "pos": [
        4,
        1,
        4
      ],
      "state": 1
    },
    {
      "pos": [
        5,
        1,
        4
      ],
      "state": 1
    },
    {
      "pos": [
        6,
        1,
        4
      ],
      "state": 1
    },
    {
      "pos": [
        7,
        1,
        4
      ],
      "state": 1
    },
    {
      "pos": [
        8,
        1,
        4
      ],
      "state": 1
    },
    {
      "pos": [
        9,
        1,
        4
      ],
      "state": 1
    },
    {
      "pos": [
        10,
        1,
        4
      ],
      "state": 1
    },
    {
      "pos": [
        11,
        1,
        4
      ],
      "state": 1
    },
    {
      "pos": [
        12,
        1,
        4
      ],
      "state": 1
    },
    {
      "pos": [
        13,
        1,
        4
      ],
      "state": 1
    },
    {
      "pos": [
        14,
        1,
        4
      ],
      "state": 1
    },
    {
      "pos": [
        15,
        1,
        4
      ],
      "state": 1
    },
    {
      "pos": [
        16,
        1,
        4
      ],
      "state": 1
    },
    {
      "pos": [
        17,
        1,
        4
      ],
      "state": 1
    },
    {
      "pos": [
        18,
        1,
        4
      ],
      "state": 1
    },
    {
      "pos": [
        1,
        1,
        5
      ],
      "state": 1
    },
    {
      "pos": [
        2,
        1,
        5
      ],
      "state": 1
    },
    {
      "pos": [
        3,
        1,
        5
      ],
      "state": 1
    },
    {
      "pos": [
        4,
        1,
        5
      ],
      "state": 1
    },
    {
      "pos": [
        5,
        1,
        5
      ],
      "state": 1
    },
    {
      "pos": [
        6,
        1,
        5
      ],
      "state": 1
    },
    {
      "pos": [
        7,
        1,
        5
      ],
      "state": 1
    },
    {
      "pos": [
        8,
        1,
        5
      ],
      "state": 1
    },
    {
      "pos": [
        9,
        1,
        5
      ],
      "state": 1
    },
    {
      "pos": [
        10,
        1,
        5
      ],
      "state": 1
    },
    {
      "pos": [
        11,
        1,
        5
      ],
      "state": 1
    },
    {
      "pos": [
        12,
        1,
        5
      ],
      "state": 1
    },
    {
      "pos": [
        13,
        1,
        5
      ],
      "state": 1
    },
    {
      "pos": [
        14,
        1,
        5
      ],
      "state": 1
    },
    {
      "pos": [
        15,
        1,
        5
      ],
      "state": 1
    },
    {
      "pos": [
        16,
        1,
        5
      ],
      "state": 1
    },
    {
      "pos": [
        17,
        1,
        5
      ],
      "state": 1
    },
    {
      "pos": [
        18,
        1,
        5
      ],
      "state": 1
    },
    {
      "pos": [
        1,
        1,
        6
      ],
      "state": 1
    },
    {
      "pos": [
        2,
        1,
        6
      ],
      "state": 1
    },
    {
      "pos": [
        3,
        1,
        6
      ],
      "state": 1
    },
    {
      "pos": [
        4,
        1,
        6
      ],
      "state": 1
    },
    {
      "pos": [
        5,
        1,
        6
      ],
      "state": 1
    },
    {
      "pos": [
        6,
        1,
        6
      ],
      "state": 1
    },
    {
      "pos": [
        7,
        1,
        6
      ],
      "state": 1
    },
    {
      "pos": [
        8,
        1,
        6
      ],
      "state": 1
    },
    {
      "pos": [
        9,
        1,
        6
      ],
      "state": 1
    },
    {
      "pos": [
        10,
        1,
        6
      ],
      "state": 1
    },
    {
      "pos": [
        11,
        1,
        6
      ],
      "state": 1
    },
    {
      "pos": [
        12,
        1,
        6
      ],
      "state": 1
    },
    {
      "pos": [
        13,
        1,
        6
      ],
      "state": 1
    },
    {
      "pos": [
        14,
        1,
        6
      ],
      "state": 1
    },
    {
      "pos": [
        15,
        1,
        6
      ],
      "state": 1
    },
    {
      "pos": [
        16,
        1,
        6
      ],
      "state": 1
    },
    {
      "pos": [
        17,
        1,
        6
      ],
      "state": 1
    },
    {
      "pos": [
        18,
        1,
        6
      ],
      "state": 1
    },
    {
      "pos": [
        1,
        1,
        7
      ],
      "state": 1
    },
    {
      "pos": [
        2,
        1,
        7
      ],
      "state": 1
    },
    {
      "pos": [
        3,
        1,
        7
      ],
      "state": 1
    },
    {
      "pos": [
        4,
        1,
        7
      ],
      "state": 1
    },
    {
      "pos": [
        5,
        1,
        7
      ],
      "state": 1
    },
    {
      "pos": [
        6,
        1,
        7
      ],
      "state": 1
    },
    {
      "pos": [
        7,
        1,
        7
      ],
      "state": 1
    },
    {
      "pos": [
        8,
        1,
        7
      ],
      "state": 1
    },
    {
      "pos": [
        9,
        1,
        7
      ],
      "state": 1
    },
    {
      "pos": [
        10,
        1,
        7
      ],
      "state": 1
    },
    {
      "pos": [
        11,
        1,
        7
      ],
      "state": 1
    },
    {
      "pos": [
        12,
        1,
        7
      ],
      "state": 1
    },
    {
      "pos": [
        13,
        1,
        7
      ],
      "state": 1
    },
    {
      "pos": [
        14,
        1,
        7
      ],
      "state": 1
    },
    {
      "pos": [
        15,
        1,
        7
      ],
      "state": 1
    },
    {
      "pos": [
        16,
        1,
        7
      ],
      "state": 1
    },
    {
      "pos": [
        17,
        1,
        7
      ],
      "state": 1
    },
    {
      "pos": [
        18,
        1,
        7
      ],
      "state": 1
    },
    {
      "pos": [
        1,
        1,
        8
      ],
      "state": 1
    },
    {
      "pos": [
        2,
        1,
        8
      ],
      "state": 1
    },
    {
      "pos": [
        3,
        1,
        8
      ],
      "state": 1
    },
    {
      "pos": [
        4,
        1,
        8
      ],
      "state": 1
    },
    {
      "pos": [
        5,
        1,
        8
      ],
      "state": 1
    },
    {
      "pos": [
        6,
        1,
        8
      ],
      "state": 1
    },
    {
      "pos": [
        7,
        1,
        8
      ],
      "state": 1
    },
    {
      "pos": [
        8,
        1,
        8
      ],
      "state": 1
    },
    {
      "pos": [
        9,
        1,
        8
      ],
      "state": 1
    },
    {
      "pos": [
        10,
        1,
        8
      ],
      "state": 1
    },
    {
      "pos": [
        11,
        1,
        8
      ],
      "state": 1
    },
    {
      "pos": [
        12,
        1,
        8
      ],
      "state": 1
    },
    {
      "pos": [
        13,
        1,
        8
      ],
      "state": 1
    },
    {
      "pos": [
        14,
        1,
        8
      ],
      "state": 1
    },
    {
      "pos": [
        15,
        1,
        8
      ],
      "state": 1
    },
    {
      "pos": [
        16,
        1,
        8
      ],
      "state": 1
    },
    {
      "pos": [
        17,
        1,
        8
      ],
      "state": 1
    },
    {
      "pos": [
        18,
        1,
        8
      ],
      "state": 1
    },
    {
      "pos": [
        1,
        1,
        9
      ],
      "state": 1
    },
    {
      "pos": [
        2,
        1,
        9
      ],
      "state": 1
    },
    {
      "pos": [
        3,
        1,
        9
      ],
      "state": 1
    },
    {
      "pos": [
        4,
        1,
        9
      ],
      "state": 1
    },
    {
      "pos": [
        5,
        1,
        9
      ],
      "state": 1
    },
    {
      "pos": [
        6,
        1,
        9
      ],
      "state": 1
    },
    {
      "pos": [
        7,
        1,
        9
      ],
      "state": 1
    },
    {
      "pos": [
        8,
        1,
        9
      ],
      "state": 1
    },
    {
      "pos": [
        9,
        1,
        9
      ],
      "state": 1
    },
    {
      "pos": [
        10,
        1,
        9
      ],
      "state": 1
    },
    {
      "pos": [
        11,
        1,
        9
      ],
      "state": 1
    },
    {
      "pos": [
        12,
        1,
        9
      ],
      "state": 1
    },
    {
      "pos": [
        13,
        1,
        9
      ],
      "state": 1
    },
    {
      "pos": [
        14,
        1,
        9
      ],
      "state": 1
    },
    {
      "pos": [
        15,
        1,
        9
      ],
      "state": 1
    },
    {
      "pos": [
        16,
        1,
        9
      ],
      "state": 1
    },
    {
      "pos": [
        17,
        1,
        9
      ],
      "state": 1
    },
    {
      "pos": [
        18,
        1,
        9
      ],
      "state": 1
    },
    {
      "pos": [
        1,
        1,
        10
      ],
      "state": 1
    },
    {
      "pos": [
        2,
        1,
        10
      ],
      "state": 1
    },
    {
      "pos": [
        3,
        1,
        10
      ],
      "state": 1
    },
    {
      "pos": [
        4,
        1,
        10
      ],
      "state": 1
    },
    {
      "pos": [
        5,
        1,
        10
      ],
      "state": 1
    },
    {
      "pos": [
        6,
        1,
        10
      ],
      "state": 1
    },
    {
      "pos": [
        7,
        1,
        10
      ],
      "state": 1
    },
    {
      "pos": [
        8,
        1,
        10
      ],
      "state": 1
    },
    {
      "pos": [
        9,
        1,
        10
      ],
      "state": 1
    },
    {
      "pos": [
        10,
        1,
        10
      ],
      "state": 1
    },
    {
      "pos": [
        11,
        1,
        10
      ],
      "state": 1
    },
    {
      "pos": [
        12,
        1,
        10
      ],
      "state": 1
    },
    {
      "pos": [
        13,
        1,
        10
      ],
      "state": 1
    },
    {
      "pos": [
        14,
        1,
        10
      ],
      "state": 1
    },
    {
      "pos": [
        15,
        1,
        10
      ],
      "state": 1
    },
    {
      "pos": [
        16,
        1,
        10
      ],
      "state": 1
    },
    {
      "pos": [
        17,
        1,
        10
      ],
      "state": 1
    },
    {
      "pos": [
        18,
        1,
        10
      ],
      "state": 1
    },
    {
      "pos": [
        1,
        1,
        11
      ],
      "state": 1
    },
    {
      "pos": [
        2,
        1,
        11
      ],
      "state": 1
    },
    {
      "pos": [
        3,
        1,
        11
      ],
      "state": 1
    },
    {
      "pos": [
        4,
        1,
        11
      ],
      "state": 1
    },
    {
      "pos": [
        5,
        1,
        11
      ],
      "state": 1
    },
    {
      "pos": [
        6,
        1,
        11
      ],
      "state": 1
    },
    {
      "pos": [
        7,
        1,
        11
      ],
      "state": 1
    },
    {
      "pos": [
        8,
        1,
        11
      ],
      "state": 1
    },
    {
      "pos": [
        9,
        1,
        11
      ],
      "state": 1
    },
    {
      "pos": [
        10,
        1,
        11
      ],
      "state": 1
    },
    {
      "pos": [
        11,
        1,
        11
      ],
      "state": 1
    },
    {
      "pos": [
        12,
        1,
        11
      ],
      "state": 1
    },
    {
      "pos": [
        13,
        1,
        11
      ],
      "state": 1
    },
    {
      "pos": [
        14,
        1,
        11
      ],
      "state": 1
    },
    {
      "pos": [
        15,
        1,
        11
      ],
      "state": 1
    },
    {
      "pos": [
        16,
        1,
        11
      ],
      "state": 1
    },
    {
      "pos": [
        17,
        1,
        11
      ],
      "state": 1
    },
    {
      "pos": [
        18,
        1,
        11
      ],
      "state": 1
    },
    {
      "pos": [
        1,
        1,
        12
      ],
      "state": 1
    },
    {
      "pos": [
        2,
        1,
        12
      ],
      "state": 1
    },
    {
      "pos": [
        3,
        1,
        12
      ],
      "state": 1
    },
    {
      "pos": [
        4,
        1,
        12
      ],
      "state": 1
    },
    {
      "pos": [
        5,
        1,
        12
      ],
      "state": 1
    },
    {
      "pos": [
        6,
        1,
        12
      ],
      "state": 1
    },
    {
      "pos": [
        7,
        1,
        12
      ],
      "state": 1
    },
    {
      "pos": [
        8,
        1,
        12
      ],
      "state": 1
    },
    {
      "pos": [
        9,
        1,
        12
      ],
      "state": 1
    },
    {
      "pos": [
        10,
        1,
        12
      ],
      "state": 1
    },
    {
      "pos": [
        11,
        1,
        12
      ],
      "state": 1
    },
    {
      "pos": [
        12,
        1,
        12
      ],
      "state": 1
    },
    {
      "pos": [
        13,
        1,
        12
      ],
      "state": 1
    },
    {
      "pos": [
        14,
        1,
        12
      ],
      "state": 1
    },
    {
      "pos": [
        15,
        1,
        12
      ],
      "state": 1
    },
    {
      "pos": [
        16,
        1,
        12
      ],
      "state": 1
    },
    {
      "pos": [
        17,
        1,
        12
      ],
      "state": 1
    },
    {
      "pos": [
        18,
        1,
        12
      ],
      "state": 1
    },
    {
      "pos": [
        1,
        1,
        13
      ],
      "state": 1
    },
    {
      "pos": [
        2,
        1,
        13
      ],
      "state": 1
    },
    {
      "pos": [
        3,
        1,
        13
      ],
      "state": 1
    },
    {
      "pos": [
        4,
        1,
        13
      ],
      "state": 1
    },
    {
      "pos": [
        5,
        1,
        13
      ],
      "state": 1
    },
    {
      "pos": [
        6,
        1,
        13
      ],
      "state": 1
    },
    {
      "pos": [
        7,
        1,
        13
      ],
      "state": 1
    },
    {
      "pos": [
        8,
        1,
        13
      ],
      "state": 1
    },
    {
      "pos": [
        9,
        1,
        13
      ],
      "state": 1
    },
    {
      "pos": [
        10,
        1,
        13
      ],
      "state": 1
    },
    {
      "pos": [
        11,
        1,
        13
      ],
      "state": 1
    },
    {
      "pos": [
        12,
        1,
        13
      ],
      "state": 1
    },
    {
      "pos": [
        13,
        1,
        13
      ],
      "state": 1
    },
    {
      "pos": [
        14,
        1,
        13
      ],
      "state": 1
    },
    {
      "pos": [
        15,
        1,
        13
      ],
      "state": 1
    },
    {
      "pos": [
        16,
        1,
        13
      ],
      "state": 1
    },
    {
      "pos": [
        17,
        1,
        13
      ],
      "state": 1
    },
    {
      "pos": [
        18,
        1,
        13
      ],
      "state": 1
    },
    {
      "pos": [
        1,
        1,
        14
      ],
      "state": 1
    },
    {
      "pos": [
        2,
        1,
        14
      ],
      "state": 1
    },
    {
      "pos": [
        3,
        1,
        14
      ],
      "state": 1
    },
    {
      "pos": [
        4,
        1,
        14
      ],
      "state": 1
    },
    {
      "pos": [
        5,
        1,
        14
      ],
      "state": 1
    },
    {
      "pos": [
        6,
        1,
        14
      ],
      "state": 1
    },
    {
      "pos": [
        7,
        1,
        14
      ],
      "state": 1
    },
    {
      "pos": [
        8,
        1,
        14
      ],
      "state": 1
    },
    {
      "pos": [
        9,
        1,
        14
      ],
      "state": 1
    },
    {
      "pos": [
        10,
        1,
        14
      ],
      "state": 1
    },
    {
      "pos": [
        11,
        1,
        14
      ],
      "state": 1
    },
    {
      "pos": [
        12,
        1,
        14
      ],
      "state": 1
    },
    {
      "pos": [
        13,
        1,
        14
      ],
      "state": 1
    },
    {
      "pos": [
        14,
        1,
        14
      ],
      "state": 1
    },
    {
      "pos": [
        15,
        1,
        14
      ],
      "state": 2
    },
    {
      "pos": [
        16,
        1,
        14
      ],
      "state": 2
    },
    {
      "pos": [
        17,
        1,
        14
      ],
      "state": 1
    },
    {
      "pos": [
        18,
        1,
        14
      ],
      "state": 1
    },
    {
      "pos": [
        1,
        1,
        15
      ],
      "state": 1
    },
    {
      "pos": [
        2,
        1,
        15
      ],
      "state": 1
    },
    {
      "pos": [
        3,
        1,
        15
      ],
      "state": 1
    },
    {
      "pos": [
        4,
        1,
        15
      ],
      "state": 1
    },
    {
      "pos": [
        5,
        1,
        15
      ],
      "state": 1
    },
    {
      "pos": [
        6,
        1,
        15
      ],
      "state": 1
    },
    {
      "pos": [
        7,
        1,
        15
      ],
      "state": 1
    },
    {
      "pos": [
        8,
        1,
        15
      ],
      "state": 1
    },
    {
      "pos": [
        9,
        1,
        15
      ],
      "state": 1
    },
    {
      "pos": [
        10,
        1,
        15
      ],
      "state": 1
    },
    {
      "pos": [
        11,
        1,
        15
      ],
      "state": 1
    },
    {
      "pos": [
        12,
        1,
        15
      ],
      "state": 1
    },
    {
      "pos": [
        13,
        1,
        15
      ],
      "state": 1
    },
    {
      "pos": [
        14,
        1,
        15
      ],
      "state": 1
    },
    {
      "pos": [
        15,
        1,
        15
      ],
      "state": 2
    },
    {
      "pos": [
        16,
        1,
        15
      ],
      "state": 2
    },
    {
      "pos": [
        17,
        1,
        15
      ],
      "state": 1
    },
    {
      "pos": [
        18,
        1,
        15
      ],
      "state": 1
    },
    {
      "pos": [
        1,
        1,
        16
      ],
      "state": 1
    },
    {
      "pos": [
        2,
        1,
        16
      ],
      "state": 1
    },
    {
      "pos": [
        3,
        1,
        16
      ],
      "state": 1
    },
    {
      "pos": [
        4,
        1,
        16
      ],
      "state": 1
    },
    {
      "pos": [
        5,
        1,
        16
      ],
      "state": 1
    },
    {
      "pos": [
        6,
        1,
        16
      ],
      "state": 1
    },
    {
      "pos": [
        7,
        1,
        16
      ],
      "state": 1
    },
    {
      "pos": [
        8,
        1,
        16
      ],
      "state": 1
    },
    {
      "pos": [
        9,
        1,
        16
      ],
      "state": 1
    },
    {
      "pos": [
        10,
        1,
        16
      ],
      "state": 1
    },
    {
      "pos": [
        11,
        1,
        16
      ],
      "state": 1
    },
    {
      "pos": [
        12,
        1,
        16
      ],
      "state": 1
    },
    {
      "pos": [
        13,
        1,
        16
      ],
      "state": 1
    },
    {
      "pos": [
        14,
        1,
        16
      ],
      "state": 1
    },
    {
      "pos": [
        15,
        1,
        16
      ],
      "state": 1
    },
    {
      "pos": [
        16,
        1,
        16
      ],
      "state": 1
    },
    {
      "pos": [
        17,
        1,
        16
      ],
      "state": 1
    },
    {
      "pos": [
        18,
        1,
        16
      ],
      "state": 1
    },
    {
      "pos": [
        1,
        1,
        17
      ],
      "state": 1
    },
    {
      "pos": [
        2,
        1,
        17
      ],
      "state": 1
    },
    {
      "pos": [
        3,
        1,
        17
      ],
      "state": 1
    },
    {
      "pos": [
        4,
        1,
        17
      ],
      "state": 1
    },
    {
      "pos": [
        5,
        1,
        17
      ],
      "state": 1
    },
    {
      "pos": [
        6,
        1,
        17
      ],
      "state": 1
    },
    {
      "pos": [
        7,
        1,
        17
      ],
      "state": 1
    },
    {
      "pos": [
        8,
        1,
        17
      ],
      "state": 1
    },
    {
      "pos": [
        9,
        1,
        17
      ],
      "state": 1
    },
    {
      "pos": [
        10,
        1,
        17
      ],
      "state": 1
    },
    {
      "pos": [
        11,
        1,
        17
      ],
      "state": 1
    },
    {
      "pos": [
        12,
        1,
        17
      ],
      "state": 1
    },
    {
      "pos": [
        13,
        1,
        17
      ],
      "state": 1
    },
    {
      "pos": [
        14,
        1,
        17
      ],
      "state": 1
    },
    {
      "pos": [
        15,
        1,
        17
      ],
      "state": 1
    },
    {
      "pos": [
        16,
        1,
        17
      ],
      "state": 1
    },
    {
      "pos": [
        17,
        1,
        17
      ],
      "state": 1
    },
    {
      "pos": [
        18,
        1,
        17
      ],
      "state": 1
    },
    {
      "pos": [
        1,
        1,
        18
      ],
      "state": 1
    },
    {
      "pos": [
        2,
        1,
        18
      ],
      "state": 1
    },
    {
      "pos": [
        3,
        1,
        18
      ],
      "state": 1
    },
    {
      "pos": [
        4,
        1,
        18
      ],
      "state": 1
    },
    {
      "pos": [
        5,
        1,
        18
      ],
      "state": 1
    },
    {
      "pos": [
        6,
        1,
        18
      ],
      "state": 1
    },
    {
      "pos": [
        7,
        1,
        18
      ],
      "state": 0
    },
    {
      "pos": [
        8,
        1,
        18
      ],
      "state": 0
    },
    {
      "pos": [
        9,
        1,
        18
      ],
      "state": 0
    },
    {
      "pos": [
        10,
        1,
        18
      ],
      "state": 0
    },
    {
      "pos": [
        11,
        1,
        18
      ],
      "state": 0
    },
    {
      "pos": [
        12,
        1,
        18
      ],
      "state": 0
    },
    {
      "pos": [
        13,
        1,
        18
      ],
      "state": 1
    },
    {
      "pos": [
        14,
        1,
        18
      ],
      "state": 1
    },
    {
      "pos": [
        15,
        1,
        18
      ],
      "state": 1
    },
    {
      "pos": [
        16,
        1,
        18
      ],
      "state": 1
    },
    {
      "pos": [
        17,
        1,
        18
      ],
      "state": 1
    },
    {
      "pos": [
        18,
        1,
        18
      ],
      "state": 1
    },
    {
      "pos": [
        7,
        1,
        19
      ],
      "state": 0
    },
    {
      "pos": [
        8,
        1,
        19
      ],
      "state": 0
    },
    {
      "pos": [
        9,
        1,
        19
      ],
      "state": 0
    },
    {
      "pos": [
        10,
        1,
        19
      ],
      "state": 0
    },
    {
      "pos": [
        11,
        1,
        19
      ],
      "state": 0
    },
    {
      "pos": [
        12,
        1,
        19
      ],
      "state": 0
    },
    {
      "pos": [
        1,
        2,
        1
      ],
      "state": 3
    },
    {
      "pos": [
        2,
        2,
        1
      ],
      "state": 4
    },
    {
      "pos": [
        3,
        2,
        1
      ],
      "state": 4
    },
    {
      "pos": [
        4,
        2,
        1
      ],
      "state": 4
    },
    {
      "pos": [
        5,
        2,
        1
      ],
      "state": 4
    },
    {
      "pos": [
        6,
        2,
        1
      ],
      "state": 1
    },
    {
      "pos": [
        7,
        2,
        1
      ],
      "state": 4
    },
    {
      "pos": [
        8,
        2,
        1
      ],
      "state": 4
    },
    {
      "pos": [
        9,
        2,
        1
      ],
      "state": 4
    },
    {
      "pos": [
        10,
        2,
        1
      ],
      "state": 4
    },
    {
      "pos": [
        11,
        2,
        1
      ],
      "state": 4
    },
    {
      "pos": [
        12,
        2,
        1
      ],
      "state": 4
    },
    {
      "pos": [
        13,
        2,
        1
      ],
      "state": 1
    },
    {
      "pos": [
        14,
        2,
        1
      ],
      "state": 4
    },
    {
      "pos": [
        15,
        2,
        1
      ],
      "state": 4
    },
    {
      "pos": [
        16,
        2,
        1
      ],
      "state": 4
    },
    {
      "pos": [
        17,
        2,
        1
      ],
      "state": 4
    },
    {
      "pos": [
        18,
        2,
        1
      ],
      "state": 3
    },
    {
      "pos": [
        1,
        2,
        2
      ],
      "state": 4
    },
    {
      "pos": [
        3,
        2,
        2
      ],
      "state": 5
    },
    {
      "pos": [
        4,
        2,
        2
      ],
      "state": 5
    },
    {
      "pos": [
        5,
        2,
        2
      ],
      "state": 5
    },
    {
      "pos": [
        6,
        2,
        2
      ],
      "state": 5
    },
    {
      "pos": [
        8,
        2,
        2
      ],
      "state": 4
    },
    {
      "pos": [
        12,
        2,
        2
      ],
      "state": 4
    },
    {
      "pos": [
        18,
        2,
        2
      ],
      "state": 4
    },
    {
      "pos": [
        1,
        2,
        3
      ],
      "state": 4
    },
    {
      "pos": [
        3,
        2,
        3
      ],
      "state": 5
    },
    {
      "pos": [
        4,
        2,
        3
      ],
      "state": 5
    },
    {
      "pos": [
        5,
        2,
        3
      ],
      "state": 5
    },
    {
      "pos": [
        6,
        2,
        3
      ],
      "state": 5
    },
    {
      "pos": [
        8,
        2,
        3
      ],
      "state": 4
    },
    {
      "pos": [
        12,
        2,
        3
      ],
      "state": 4
    },
    {
      "pos": [
        15,
        2,
        3
      ],
      "state": 6
    },
    {
      "pos": [
        16,
        2,
        3
      ],
      "state": 6
    },
    {
      "pos": [
        18,
        2,
        3
      ],
      "state": 4
    },
    {
      "pos": [
        1,
        2,
        4
      ],
      "state": 4
    },
    {
      "pos": [
        3,
        2,
        4
      ],
      "state": 5
    },
    {
      "pos": [
        4,
        2,
        4
      ],
      "state": 5
    },
    {
      "pos": [
        5,
        2,
        4
      ],
      "state": 5
    },
    {
      "pos": [
        6,
        2,
        4
      ],
      "state": 5
    },
    {
      "pos": [
        8,
        2,
        4
      ],
      "state": 4
    },
    {
      "pos": [
        12,
        2,
        4
      ],
      "state": 4
    },
    {
      "pos": [
        15,
        2,
        4
      ],
      "state": 6
    },
    {
      "pos": [
        16,
        2,
        4
      ],
      "state": 6
    },
    {
      "pos": [
        18,
        2,
        4
      ],
      "state": 4
    },
    {
      "pos": [
        1,
        2,
        5
      ],
      "state": 4
    },
    {
      "pos": [
        3,
        2,
        5
      ],
      "state": 5
    },
    {
      "pos": [
        4,
        2,
        5
      ],
      "state": 5
    },
    {
      "pos": [
        5,
        2,
        5
      ],
      "state": 5
    },
    {
      "pos": [
        6,
        2,
        5
      ],
      "state": 5
    },
    {
      "pos": [
        8,
        2,
        5
      ],
      "state": 4
    },
    {
      "pos": [
        12,
        2,
        5
      ],
      "state": 4
    },
    {
      "pos": [
        18,
        2,
        5
      ],
      "state": 4
    },
    {
      "pos": [
        1,
        2,
        6
      ],
      "state": 1
    },
    {
      "pos": [
        3,
        2,
        6
      ],
      "state": 5
    },
    {
      "pos": [
        4,
        2,
        6
      ],
      "state": 5
    },
    {
      "pos": [
        5,
        2,
        6
      ],
      "state": 5
    },
    {
      "pos": [
        6,
        2,
        6
      ],
      "state": 5
    },
    {
      "pos": [
        18,
        2,
        6
      ],
      "state": 1
    },
    {
      "pos": [
        1,
        2,
        7
      ],
      "state": 4
    },
    {
      "pos": [
        3,
        2,
        7
      ],
      "state": 5
    },
    {
      "pos": [
        4,
        2,
        7
      ],
      "state": 5
    },
    {
      "pos": [
        5,
        2,
        7
      ],
      "state": 5
    },
    {
      "pos": [
        6,
        2,
        7
      ],
      "state": 5
    },
    {
      "pos": [
        8,
        2,
        7
      ],
      "state": 4
    },
    {
      "pos": [
        12,
        2,
        7
      ],
      "state": 4
    },
    {
      "pos": [
        18,
        2,
        7
      ],
      "state": 4
    },
    {
      "pos": [
        1,
        2,
        8
      ],
      "state": 4
    },
    {
      "pos": [
        3,
        2,
        8
      ],
      "state": 5
    },
    {
      "pos": [
        4,
        2,
        8
      ],
      "state": 5
    },
    {
      "pos": [
        5,
        2,
        8
      ],
      "state": 5
    },
    {
      "pos": [
        6,
        2,
        8
      ],
      "state": 5
    },
    {
      "pos": [
        8,
        2,
        8
      ],
      "state": 4
    },
    {
      "pos": [
        12,
        2,
        8
      ],
      "state": 4
    },
    {
      "pos": [
        18,
        2,
        8
      ],
      "state": 4
    },
    {
      "pos": [
        1,
        2,
        9
      ],
      "state": 4
    },
    {
      "pos": [
        2,
        2,
        9
      ],
      "state": 4
    },
    {
      "pos": [
        3,
        2,
        9
      ],
      "state": 4
    },
    {
      "pos": [
        4,
        2,
        9
      ],
      "state": 4
    },
    {
      "pos": [
        5,
        2,
        9
      ],
      "state": 4
    },
    {
      "pos": [
        6,
        2,
        9
      ],
      "state": 4
    },
    {
      "pos": [
        7,
        2,
        9
      ],
      "state": 4
    },
    {
      "pos": [
        8,
        2,
        9
      ],
      "state": 4
    },
    {
      "pos": [
        9,
        2,
        9
      ],
      "state": 4
    },
    {
      "pos": [
        12,
        2,
        9
      ],
      "state": 4
    },
    {
      "pos": [
        13,
        2,
        9
      ],
      "state": 4
    },
    {
      "pos": [
        18,
        2,
        9
      ],
      "state": 4
    },
    {
      "pos": [
        1,
        2,
        10
      ],
      "state": 4
    },
    {
      "pos": [
        8,
        2,
        10
      ],
      "state": 4
    },
    {
      "pos": [
        12,
        2,
        10
      ],
      "state": 4
    },
    {
      "pos": [
        18,
        2,
        10
      ],
      "state": 4
    },
    {
      "pos": [
        1,
        2,
        11
      ],
      "state": 4
    },
    {
      "pos": [
        8,
        2,
        11
      ],
      "state": 4
    },
    {
      "pos": [
        12,
        2,
        11
      ],
      "state": 4
    },
    {
      "pos": [
        18,
        2,
        11
      ],
      "state": 4
    },
    {
      "pos": [
        1,
        2,
        12
      ],
      "state": 4
    },
    {
      "pos": [
        8,
        2,
        12
      ],
      "state": 4
    },
    {
      "pos": [
        12,
        2,
        12
      ],
      "state": 4
    },
    {
      "pos": [
        18,
        2,
        12
      ],
      "state": 4
    },
    {
      "pos": [
        1,
        2,
        13
      ],
      "state": 1
    },
    {
      "pos": [
        8,
        2,
        13
      ],
      "state": 4
    },
    {
      "pos": [
        12,
        2,
        13
      ],
      "state": 4
    },
    {
      "pos": [
        18,
        2,
        13
      ],
      "state": 1
    },
    {
      "pos": [
        1,
        2,
        14
      ],
      "state": 4
    },
    {
      "pos": [
        8,
        2,
        14
      ],
      "state": 4
    },
    {
      "pos": [
        12,
        2,
        14
      ],
      "state": 4
    },
    {
      "pos": [
        18,
        2,
        14
      ],
      "state": 4
    },
    {
      "pos": [
        1,
        2,
        15
      ],
      "state": 4
    },
    {
      "pos": [
        8,
        2,
        15
      ],
      "state": 4
    },
    {
      "pos": [
        12,
        2,
        15
      ],
      "state": 4
    },
    {
      "pos": [
        18,
        2,
        15
      ],
      "state": 4
    },
    {
      "pos": [
        1,
        2,
        16
      ],
      "state": 4
    },
    {
      "pos": [
        8,
        2,
        16
      ],
      "state": 4
    },
    {
      "pos": [
        12,
        2,
        16
      ],
      "state": 4
    },
    {
      "pos": [
        18,
        2,
        16
      ],
      "state": 4
    },
    {
      "pos": [
        1,
        2,
        17
      ],
      "state": 4
    },
    {
      "pos": [
        8,
        2,
        17
      ],
      "state": 4
    },
    {
      "pos": [
        9,
        2,
        17
      ],
      "state": 3
    },
    {
      "pos": [
        10,
        2,
        17
      ],
      "state": 3
    },
    {
      "pos": [
        11,
        2,
        17
      ],
      "state": 3
    },
    {
      "pos": [
        12,
        2,
        17
      ],
      "state": 4
    },
    {
      "pos": [
        18,
        2,
        17
      ],
      "state": 4
    },
    {
      "pos": [
        1,
        2,
        18
      ],
      "state": 3
    },
    {
      "pos": [
        2,
        2,
        18
      ],
      "state": 4
    },
    {
      "pos": [
        3,
        2,
        18
      ],
      "state": 4
    },
    {
      "pos": [
        4,
        2,
        18
      ],
      "state": 4
    },
    {
      "pos": [
        5,
        2,
        18
      ],
      "state": 4
    },
    {
      "pos": [
        6,
        2,
        18
      ],
      "state": 1
    },
    {
      "pos": [
        7,
        2,
        18
      ],
      "state": 4
    },
    {
      "pos": [
        8,
        2,
        18
      ],
      "state": 4
    },
    {
      "pos": [
        9,
        2,
        18
      ],
      "state": 4
    },
    {
      "pos": [
        10,
        2,
        18
      ],
      "state": 4
    },
    {
      "pos": [
        11,
        2,
        18
      ],
      "state": 4
    },
    {
      "pos": [
        12,
        2,
        18
      ],
      "state": 4
    },
    {
      "pos": [
        13,
        2,
        18
      ],
      "state": 1
    },
    {
      "pos": [
        14,
        2,
        18
      ],
      "state": 4
    },
    {
      "pos": [
        15,
        2,
        18
      ],
      "state": 4
    },
    {
      "pos": [
        16,
        2,
        18
      ],
      "state": 4
    },
    {
      "pos": [
        17,
        2,
        18
      ],
      "state": 4
    },
    {
      "pos": [
        18,
        2,
        18
      ],
      "state": 3
    },
    {
      "pos": [
        1,
        3,
        1
      ],
      "state": 3
    },
    {
      "pos": [
        2,
        3,
        1
      ],
      "state": 4
    },
    {
      "pos": [
        3,
        3,
        1
      ],
      "state": 4
    },
    {
      "pos": [
        4,
        3,
        1
      ],
      "state": 7
    },
    {
      "pos": [
        5,
        3,
        1
      ],
      "state": 7
    },
    {
      "pos": [
        6,
        3,
        1
      ],
      "state": 1
    },
    {
      "pos": [
        7,
        3,
        1
      ],
      "state": 4
    },
    {
      "pos": [
        8,
        3,
        1
      ],
      "state": 4
    },
    {
      "pos": [
        9,
        3,
        1
      ],
      "state": 4
    },
    {
      "pos": [
        10,
        3,
        1
      ],
      "state": 4
    },
    {
      "pos": [
        11,
        3,
        1
      ],
      "state": 4
    },
    {
      "pos": [
        12,
        3,
        1
      ],
      "state": 4
    },
    {
      "pos": [
        13,
        3,
        1
      ],
      "state": 1
    },
    {
      "pos": [
        14,
        3,
        1
      ],
      "state": 7
    },
    {
      "pos": [
        15,
        3,
        1
      ],
      "state": 7
    },
    {
      "pos": [
        16,
        3,
        1
      ],
      "state": 4
    },
    {
      "pos": [
        17,
        3,
        1
      ],
      "state": 4
    },
    {
      "pos": [
        18,
        3,
        1
      ],
      "state": 3
    },
    {
      "pos": [
        1,
        3,
        2
      ],
      "state": 4
    },
    {
      "pos": [
        8,
        3,
        2
      ],
      "state": 4
    },
    {
      "pos": [
        12,
        3,
        2
      ],
      "state": 4
    },
    {
      "pos": [
        18,
        3,
        2
      ],
      "state": 4
    },
    {
      "pos": [
        1,
        3,
        3
      ],
      "state": 4
    },
    {
      "pos": [
        8,
        3,
        3
      ],
      "state": 4
    },
    {
      "pos": [
        12,
        3,
        3
      ],
      "state": 4
    },
    {
      "pos": [
        18,
        3,
        3
      ],
      "state": 4
    },
    {
      "pos": [
        1,
        3,
        4
      ],
      "state": 7
    },
    {
      "pos": [
        8,
        3,
        4
      ],
      "state": 4
    },
    {
      "pos": [
        12,
        3,
        4
      ],
      "state": 4
    },
    {
      "pos": [
        18,
        3,
        4
      ],
      "state": 7
    },
    {
      "pos": [
        1,
        3,
        5
      ],
      "state": 7
    },
    {
      "pos": [
        8,
        3,
        5
      ],
      "state": 4
    },
    {
      "pos": [
        12,
        3,
        5
      ],
      "state": 4
    },
    {
      "pos": [
        18,
        3,
        5
      ],
      "state": 7
    },
    {
      "pos": [
        1,
        3,
        6
      ],
      "state": 1
    },
    {
      "pos": [
        18,
        3,
        6
      ],
      "state": 1
    },
    {
      "pos": [
        1,
        3,
        7
      ],
      "state": 4
    },
    {
      "pos": [
        8,
        3,
        7
      ],
      "state": 4
    },
    {
      "pos": [
        12,
        3,
        7
      ],
      "state": 4
    },
    {
      "pos": [
        18,
        3,
        7
      ],
      "state": 4
    },
    {
      "pos": [
        1,
        3,
        8
      ],
      "state": 4
    },
    {
      "pos": [
        8,
        3,
        8
      ],
      "state": 4
    },
    {
      "pos": [
        12,
        3,
        8
      ],
      "state": 4
    },
    {
      "pos": [
        18,
        3,
        8
      ],
      "state": 4
    },
    {
      "pos": [
        1,
        3,
        9
      ],
      "state": 4
    },
    {
      "pos": [
        2,
        3,
        9
      ],
      "state": 4
    },
    {
      "pos": [
        3,
        3,
        9
      ],
      "state": 4
    },
    {
      "pos": [
        4,
        3,
        9
      ],
      "state": 4
    },
    {
      "pos": [
        5,
        3,
        9
      ],
      "state": 4
    },
    {
      "pos": [
        6,
        3,
        9
      ],
      "state": 4
    },
    {
      "pos": [
        7,
        3,
        9
      ],
      "state": 4
    },
    {
      "pos": [
        8,
        3,
        9
      ],
      "state": 4
    },
    {
      "pos": [
        9,
        3,
        9
      ],
      "state": 4
    },
    {
      "pos": [
        12,
        3,
        9
      ],
      "state": 4
    },
    {
      "pos": [
        13,
        3,
        9
      ],
      "state": 4
    },
    {
      "pos": [
        18,
        3,
        9
      ],
      "state": 4
    },
    {
      "pos": [
        1,
        3,
        10
      ],
      "state": 4
    },
    {
      "pos": [
        8,
        3,
        10
      ],
      "state": 4
    },
    {
      "pos": [
        12,
        3,
        10
      ],
      "state": 4
    },
    {
      "pos": [
        18,
        3,
        10
      ],
      "state": 4
    },
    {
      "pos": [
        1,
        3,
        11
      ],
      "state": 4
    },
    {
      "pos": [
        4,
        3,
        11
      ],
      "state": 8
    },
    {
      "pos": [
        8,
        3,
        11
      ],
      "state": 4
    },
    {
      "pos": [
        12,
        3,
        11
      ],
      "state": 4
    },
    {
      "pos": [
        18,
        3,
        11
      ],
      "state": 4
    },
    {
      "pos": [
        1,
        3,
        12
      ],
      "state": 4
    },
    {
      "pos": [
        8,
        3,
        12
      ],
      "state": 4
    },
    {
      "pos": [
        10,
        3,
        12
      ],
      "state": 8
    },
    {
      "pos": [
        12,
        3,
        12
      ],
      "state": 4
    },
    {
      "pos": [
        14,
        3,
        12
      ],
      "state": 8
    },
    {
      "pos": [
        18,
        3,
        12
      ],
      "state": 4
    },
    {
      "pos": [
        1,
        3,
        13
      ],
      "state": 1
    },
    {
      "pos": [
        8,
        3,
        13
      ],
      "state": 4
    },
    {
      "pos": [
        12,
        3,
        13
      ],
      "state": 4
    },
    {
      "pos": [
        18,
        3,
        13
      ],
      "state": 1
    },
    {
      "pos": [
        1,
        3,
        14
      ],
      "state": 7
    },
    {
      "pos": [
        8,
        3,
        14
      ],
      "state": 4
    },
    {
      "pos": [
        12,
        3,
        14
      ],
      "state": 4
    },
    {
      "pos": [
        18,
        3,
        14
      ],
      "state": 7
    },
    {
      "pos": [
        1,
        3,
        15
      ],
      "state": 7
    },
    {
      "pos": [
        6,
        3,
        15
      ],
      "state": 8
    },
    {
      "pos": [
        8,
        3,
        15
      ],
      "state": 4
    },
    {
      "pos": [
        12,
        3,
        15
      ],
      "state": 4
    },
    {
      "pos": [
        16,
        3,
        15
      ],
      "state": 8
    },
    {
      "pos": [
        18,
        3,
        15
      ],
      "state": 7
    },
    {
      "pos": [
        1,
        3,
        16
      ],
      "state": 4
    },
    {
      "pos": [
        8,
        3,
        16
      ],
      "state": 4
    },
    {
      "pos": [
        12,
        3,
        16
      ],
      "state": 4
    },
    {
      "pos": [
        18,
        3,
        16
      ],
      "state": 4
    },
    {
      "pos": [
        1,
        3,
        17
      ],
      "state": 4
    },
    {
      "pos": [
        8,
        3,
        17
      ],
      "state": 4
    },
    {
      "pos": [
        9,
        3,
        17
      ],
      "state": 3
    },
    {
      "pos": [
        10,
        3,
        17
      ],
      "state": 3
    },
    {
      "pos": [
        11,
        3,
        17
      ],
      "state": 3
    },
    {
      "pos": [
        12,
        3,
        17
      ],
      "state": 4
    },
    {
      "pos": [
        18,
        3,
        17
      ],
      "state": 4
    },
    {
      "pos": [
        1,
        3,
        18
      ],
      "state": 3
    },
    {
      "pos": [
        2,
        3,
        18
      ],
      "state": 4
    },
    {
      "pos": [
        3,
        3,
        18
      ],
      "state": 4
    },
    {
      "pos": [
        4,
        3,
        18
      ],
      "state": 7
    },
    {
      "pos": [
        5,
        3,
        18
      ],
      "state": 7
    },
    {
      "pos": [
        6,
        3,
        18
      ],
      "state": 1
    },
    {
      "pos": [
        7,
        3,
        18
      ],
      "state": 4
    },
    {
      "pos": [
        8,
        3,
        18
      ],
      "state": 4
    },
    {
      "pos": [
        9,
        3,
        18
      ],
      "state": 4
    },
    {
      "pos": [
        10,
        3,
        18
      ],
      "state": 4
    },
    {
      "pos": [
        11,
        3,
        18
      ],
      "state": 4
    },
    {
      "pos": [
        12,
        3,
        18
      ],
      "state": 4
    },
    {
      "pos": [
        13,
        3,
        18
      ],
      "state": 1
    },
    {
      "pos": [
        14,
        3,
        18
      ],
      "state": 7
    },
    {
      "pos": [
        15,
        3,
        18
      ],
      "state": 7
    },
    {
      "pos": [
        16,
        3,
        18
      ],
      "state": 4
    },
    {
      "pos": [
        17,
        3,
        18
      ],
      "state": 4
    },
    {
      "pos": [
        18,
        3,
        18
      ],
      "state": 3
    },
    {
      "pos": [
        1,
        4,
        1
      ],
      "state": 3
    },
    {
      "pos": [
        2,
        4,
        1
      ],
      "state": 4
    },
    {
      "pos": [
        3,
        4,
        1
      ],
      "state": 4
    },
    {
      "pos": [
        4,
        4,
        1
      ],
      "state": 7
    },
    {
      "pos": [
        5,
        4,
        1
      ],
      "state": 7
    },
    {
      "pos": [
        6,
        4,
        1
      ],
      "state": 1
    },
    {
      "pos": [
        7,
        4,
        1
      ],
      "state": 4
    },
    {
      "pos": [
        8,
        4,
        1
      ],
      "state": 4
    },
    {
      "pos": [
        9,
        4,
        1
      ],
      "state": 4
    },
    {
      "pos": [
        10,
        4,
        1
      ],
      "state": 4
    },
    {
      "pos": [
        11,
        4,
        1
      ],
      "state": 4
    },
    {
      "pos": [
        12,
        4,
        1
      ],
      "state": 4
    },
    {
      "pos": [
        13,
        4,
        1
      ],
      "state": 1
    },
    {
      "pos": [
        14,
        4,
        1
      ],
      "state": 7
    },
    {
      "pos": [
        15,
        4,
        1
      ],
      "state": 7
    },
    {
      "pos": [
        16,
        4,
        1
      ],
      "state": 4
    },
    {
      "pos": [
        17,
        4,
        1
      ],
      "state": 4
    },
    {
      "pos": [
        18,
        4,
        1
      ],
      "state": 3
    },
    {
      "pos": [
        1,
        4,
        2
      ],
      "state": 4
    },
    {
      "pos": [
        8,
        4,
        2
      ],
      "state": 4
    },
    {
      "pos": [
        12,
        4,
        2
      ],
      "state": 4
    },
    {
      "pos": [
        18,
        4,
        2
      ],
      "state": 4
    },
    {
      "pos": [
        1,
        4,
        3
      ],
      "state": 4
    },
    {
      "pos": [
        8,
        4,
        3
      ],
      "state": 4
    },
    {
      "pos": [
        12,
        4,
        3
      ],
      "state": 4
    },
    {
      "pos": [
        18,
        4,
        3
      ],
      "state": 4
    },
    {
      "pos": [
        1,
        4,
        4
      ],
      "state": 7
    },
    {
      "pos": [
        8,
        4,
        4
      ],
      "state": 4
    },
    {
      "pos": [
        12,
        4,
        4
      ],
      "state": 4
    },
    {
      "pos": [
        18,
        4,
        4
      ],
      "state": 7
    },
    {
      "pos": [
        1,
        4,
        5
      ],
      "state": 7
    },
    {
      "pos": [
        8,
        4,
        5
      ],
      "state": 4
    },
    {
      "pos": [
        12,
        4,
        5
      ],
      "state": 4
    },
    {
      "pos": [
        18,
        4,
        5
      ],
      "state": 7
    },
    {
      "pos": [
        1,
        4,
        6
      ],
      "state": 1
    },
    {
      "pos": [
        8,
        4,
        6
      ],
      "state": 4
    },
    {
      "pos": [
        12,
        4,
        6
      ],
      "state": 4
    },
    {
      "pos": [
        18,
        4,
        6
      ],
      "state": 1
    },
    {
      "pos": [
        1,
        4,
        7
      ],
      "state": 4
    },
    {
      "pos": [
        8,
        4,
        7
      ],
      "state": 4
    },
    {
      "pos": [
        12,
        4,
        7
      ],
      "state": 4
    },
    {
      "pos": [
        18,
        4,
        7
      ],
      "state": 4
    },
    {
      "pos": [
        1,
        4,
        8
      ],
      "state": 4
    },
    {
      "pos": [
        8,
        4,
        8
      ],
      "state": 4
    },
    {
      "pos": [
        12,
        4,
        8
      ],
      "state": 4
    },
    {
      "pos": [
        18,
        4,
        8
      ],
      "state": 4
    },
    {
      "pos": [
        1,
        4,
        9
      ],
      "state": 4
    },
    {
      "pos": [
        2,
        4,
        9
      ],
      "state": 4
    },
    {
      "pos": [
        3,
        4,
        9
      ],
      "state": 4
    },
    {
      "pos": [
        4,
        4,
        9
      ],
      "state": 4
    },
    {
      "pos": [
        5,
        4,
        9
      ],
      "state": 4
    },
    {
      "pos": [
        6,
        4,
        9
      ],
      "state": 4
    },
    {
      "pos": [
        7,
        4,
        9
      ],
      "state": 4
    },
    {
      "pos": [
        8,
        4,
        9
      ],
      "state": 4
    },
    {
      "pos": [
        9,
        4,
        9
      ],
      "state": 4
    },
    {
      "pos": [
        10,
        4,
        9
      ],
      "state": 4
    },
    {
      "pos": [
        11,
        4,
        9
      ],
      "state": 4
    },
    {
      "pos": [
        12,
        4,
        9
      ],
      "state": 4
    },
    {
      "pos": [
        13,
        4,
        9
      ],
      "state": 4
    },
    {
      "pos": [
        18,
        4,
        9
      ],
      "state": 4
    },
    {
      "pos": [
        1,
        4,
        10
      ],
      "state": 4
    },
    {
      "pos": [
        8,
        4,
        10
      ],
      "state": 4
    },
    {
      "pos": [
        12,
        4,
        10
      ],
      "state": 4
    },
    {
      "pos": [
        18,
        4,
        10
      ],
      "state": 4
    },
    {
      "pos": [
        1,
        4,
        11
      ],
      "state": 4
    },
    {
      "pos": [
        8,
        4,
        11
      ],
      "state": 4
    },
    {
      "pos": [
        12,
        4,
        11
      ],
      "state": 4
    },
    {
      "pos": [
        18,
        4,
        11
      ],
      "state": 4
    },
    {
      "pos": [
        1,
        4,
        12
      ],
      "state": 4
    },
    {
      "pos": [
        8,
        4,
        12
      ],
      "state": 4
    },
    {
      "pos": [
        12,
        4,
        12
      ],
      "state": 4
    },
    {
      "pos": [
        18,
        4,
        12
      ],
      "state": 4
    },
    {
      "pos": [
        1,
        4,
        13
      ],
      "state": 1
    },
    {
      "pos": [
        8,
        4,
        13
      ],
      "state": 4
    },
    {
      "pos": [
        12,
        4,
        13
      ],
      "state": 4
    },
    {
      "pos": [
        18,
        4,
        13
      ],
      "state": 1
    },
    {
      "pos": [
        1,
        4,
        14
      ],
      "state": 7
    },
    {
      "pos": [
        8,
        4,
        14
      ],
      "state": 4
    },
    {
      "pos": [
        12,
        4,
        14
      ],
      "state": 4
    },
    {
      "pos": [
        18,
        4,
        14
      ],
      "state": 7
    },
    {
      "pos": [
        1,
        4,
        15
      ],
      "state": 7
    },
    {
      "pos": [
        8,
        4,
        15
      ],
      "state": 4
    },
    {
      "pos": [
        12,
        4,
        15
      ],
      "state": 4
    },
    {
      "pos": [
        18,
        4,
        15
      ],
      "state": 7
    },
    {
      "pos": [
        1,
        4,
        16
      ],
      "state": 4
    },
    {
      "pos": [
        8,
        4,
        16
      ],
      "state": 4
    },
    {
      "pos": [
        12,
        4,
        16
      ],
      "state": 4
    },
    {
      "pos": [
        18,
        4,
        16
      ],
      "state": 4
    },
    {
      "pos": [
        1,
        4,
        17
      ],
      "state": 4
    },
    {
      "pos": [
        8,
        4,
        17
      ],
      "state": 4
    },
    {
      "pos": [
        9,
        4,
        17
      ],
      "state": 3
    },
    {
      "pos": [
        10,
        4,
        17
      ],
      "state": 3
    },
    {
      "pos": [
        11,
        4,
        17
      ],
      "state": 3
    },
    {
      "pos": [
        12,
        4,
        17
      ],
      "state": 4
    },
    {
      "pos": [
        18,
        4,
        17
      ],
      "state": 4
    },
    {
      "pos": [
        1,
        4,
        18
      ],
      "state": 3
    },
    {
      "pos": [
        2,
        4,
        18
      ],
      "state": 4
    },
    {
      "pos": [
        3,
        4,
        18
      ],
      "state": 4
    },
    {
      "pos": [
        4,
        4,
        18
      ],
      "state": 7
    },
    {
      "pos": [
        5,
        4,
        18
      ],
      "state": 7
    },
    {
      "pos": [
        6,
        4,
        18
      ],
      "state": 1
    },
    {
      "pos": [
        7,
        4,
        18
      ],
      "state": 4
    },
    {
      "pos": [
        8,
        4,
        18
      ],
      "state": 4
    },
    {
      "pos": [
        9,
        4,
        18
      ],
      "state": 4
    },
    {
      "pos": [
        10,
        4,
        18
      ],
      "state": 4
    },
    {
      "pos": [
        11,
        4,
        18
      ],
      "state": 4
    },
    {
      "pos": [
        12,
        4,
        18
      ],
      "state": 4
    },
    {
      "pos": [
        13,
        4,
        18
      ],
      "state": 1
    },
    {
      "pos": [
        14,
        4,
        18
      ],
      "state": 7
    },
    {
      "pos": [
        15,
        4,
        18
      ],
      "state": 7
    },
    {
      "pos": [
        16,
        4,
        18
      ],
      "state": 4
    },
    {
      "pos": [
        17,
        4,
        18
      ],
      "state": 4
    },
    {
      "pos": [
        18,
        4,
        18
      ],
      "state": 3
    },
    {
      "pos": [
        1,
        5,
        1
      ],
      "state": 3
    },
    {
      "pos": [
        2,
        5,
        1
      ],
      "state": 4
    },
    {
      "pos": [
        3,
        5,
        1
      ],
      "state": 4
    },
    {
      "pos": [
        4,
        5,
        1
      ],
      "state": 4
    },
    {
      "pos": [
        5,
        5,
        1
      ],
      "state": 4
    },
    {
      "pos": [
        6,
        5,
        1
      ],
      "state": 1
    },
    {
      "pos": [
        7,
        5,
        1
      ],
      "state": 4
    },
    {
      "pos": [
        8,
        5,
        1
      ],
      "state": 4
    },
    {
      "pos": [
        9,
        5,
        1
      ],
      "state": 4
    },
    {
      "pos": [
        10,
        5,
        1
      ],
      "state": 4
    },
    {
      "pos": [
        11,
        5,
        1
      ],
      "state": 4
    },
    {
      "pos": [
        12,
        5,
        1
      ],
      "state": 4
    },
    {
      "pos": [
        13,
        5,
        1
      ],
      "state": 1
    },
    {
      "pos": [
        14,
        5,
        1
      ],
      "state": 4
    },
    {
      "pos": [
        15,
        5,
        1
      ],
      "state": 4
    },
    {
      "pos": [
        16,
        5,
        1
      ],
      "state": 4
    },
    {
      "pos": [
        17,
        5,
        1
      ],
      "state": 4
    },
    {
      "pos": [
        18,
        5,
        1
      ],
      "state": 3
    },
    {
      "pos": [
        1,
        5,
        2
      ],
      "state": 4
    },
    {
      "pos": [
        2,
        5,
        2
      ],
      "state": 1
    },
    {
      "pos": [
        3,
        5,
        2
      ],
      "state": 1
    },
    {
      "pos": [
        4,
        5,
        2
      ],
      "state": 1
    },
    {
      "pos": [
        5,
        5,
        2
      ],
      "state": 1
    },
    {
      "pos": [
        6,
        5,
        2
      ],
      "state": 1
    },
    {
      "pos": [
        7,
        5,
        2
      ],
      "state": 1
    },
    {
      "pos": [
        8,
        5,
        2
      ],
      "state": 1
    },
    {
      "pos": [
        9,
        5,
        2
      ],
      "state": 1
    },
    {
      "pos": [
        10,
        5,
        2
      ],
      "state": 1
    },
    {
      "pos": [
        11,
        5,
        2
      ],
      "state": 1
    },
    {
      "pos": [
        12,
        5,
        2
      ],
      "state": 1
    },
    {
      "pos": [
        13,
        5,
        2
      ],
      "state": 1
    },
    {
      "pos": [
        14,
        5,
        2
      ],
      "state": 1
    },
    {
      "pos": [
        15,
        5,
        2
      ],
      "state": 1
    },
    {
      "pos": [
        16,
        5,
        2
      ],
      "state": 1
    },
    {
      "pos": [
        17,
        5,
        2
      ],
      "state": 1
    },
    {
      "pos": [
        18,
        5,
        2
      ],
      "state": 4
    },
    {
      "pos": [
        1,
        5,
        3
      ],
      "state": 4
    },
    {
      "pos": [
        2,
        5,
        3
      ],
      "state": 1
    },
    {
      "pos": [
        3,
        5,
        3
      ],
      "state": 1
    },
    {
      "pos": [
        4,
        5,
        3
      ],
      "state": 1
    },
    {
      "pos": [
        5,
        5,
        3
      ],
      "state": 1
    },
    {
      "pos": [
        6,
        5,
        3
      ],
      "state": 1
    },
    {
      "pos": [
        7,
        5,
        3
      ],
      "state": 1
    },
    {
      "pos": [
        8,
        5,
        3
      ],
      "state": 1
    },
    {
      "pos": [
        9,
        5,
        3
      ],
      "state": 1
    },
    {
      "pos": [
